Workbook

Sheet tab4
A1: Rtime | B1: hra_rs | C1: hla_rs | D1: rcirOn | E1: lcirOn | F1: snow | G1: wet | H1: TR | I1: TC | J1: TA | L1: czas zdarzenia | M1: AP szyn | N1: AP zam. | O1: Obw.wzc. | P1: Obw.zam. | Q1: śnieg | R1: opad | S1: TSG [°C] | T1: TSZ [°C] | U1: TP [°C] | W1: Zignorować wartości błędne? | Y1: NIE | AA1: LEGENDA
A2: 6583e951 | B2: 0 | C2: 0 | D2: 0 | E2: 0 | F2: 0 | G2: 0 | H2: 30 | I2: 2d | J2: 0 | L2: =IF(AND((((HEX2DEC(A2)/60)/60)/24)+DATE(1970,1,1) >= DATE(YEAR((((HEX2DEC(A2)/60)/60)/24)+DATE(1970,1,1)),3,24)+WEEKDAY(DATE(YEAR((((HEX2DEC(A2)/60)/60)/24)+DATE(1970,1,1)),3,31)-1), (((HEX2DEC(A2)/60)/60)/24)+DATE(1970,1,1) < DATE(YEAR((((HEX2DEC(A2)/60)/60)/24)+DATE(1970,1,1)),11,1)+26-WEEKDAY(DATE(YEAR((((HEX2DEC(A2)/60)/60)/24)+DATE(1970,1,1)),11,1)-1)),(((HEX2DEC(A2)/60)/60)/24)+DATE(1970,1,1)+2/24,(((HEX2DEC(A2)/60)/60)/24)+DATE(1970,1,1)+1/24) -> 45281.354 | M2: =IF('tab4'!$B2=0,0,IF('tab4'!$B2=1,1,IF('tab4'!$B2=4,2,IF('tab4'!$B2=5,3,IF('tab4'!$B2=6,4,IF(AND('tab4'!$B2=80,$X$2=2),0,-1)))))) -> 0 | N2: =IF('tab4'!$C2=0,0,IF('tab4'!$C2=1,1,IF('tab4'!$C2=4,2,IF('tab4'!$C2=5,3,IF('tab4'!$C2=6,4,IF(AND('tab4'!$C2=80,$X$2=2),0,-1)))))) -> 0 | O2: =D2 -> 0 | P2: =E2 -> 0 | Q2: =F2 -> 0 | R2: =G2 -> 0 | S2: =IF(HEX2DEC(H2) >= 32768, (HEX2DEC(H2) - 65535 - 1)/10, IF(HEX2DEC(H2) = 32767, IF($X$2=2, S3, 32767), HEX2DEC(H2)/10 )) -> 4.8 | T2: =IF(HEX2DEC(I2) >= 32768, (HEX2DEC(I2) - 65535 - 1)/10, IF(HEX2DEC(I2) = 32767, IF($X$2=2, T3, 32767), HEX2DEC(I2)/10 )) -> 4.5 | U2: =IF(HEX2DEC(J2) >= 32768, (HEX2DEC(J2) - 65535 - 1)/10, IF(HEX2DEC(J2) = 32767, IF($X$2=2, U3, 32767), IF(OR(AND(H2="7fff", I2="7fff", J2="0",$X$2=2),AND(ABS(T2)>2, J2="0",$X$2=2)),U3,HEX2DEC(J2)/10 ))) -> 5.2 | X2: 2 | Y2: TAK | AA2: TP - temperatura powietrza | AE2: TSZ - temperatura szyny zimnej
A3: 6583e951 | B3: 0 | C3: 0 | D3: 0 | E3: 0 | F3: 0 | G3: 0 | H3: 30 | I3: 2d | J3: 34 | L3: =IF(AND((((HEX2DEC(A3)/60)/60)/24)+DATE(1970,1,1) >= DATE(YEAR((((HEX2DEC(A3)/60)/60)/24)+DATE(1970,1,1)),3,24)+WEEKDAY(DATE(YEAR((((HEX2DEC(A3)/60)/60)/24)+DATE(1970,1,1)),3,31)-1), (((HEX2DEC(A3)/60)/60)/24)+DATE(1970,1,1) < DATE(YEAR((((HEX2DEC(A3)/60)/60)/24)+DATE(1970,1,1)),11,1)+26-WEEKDAY(DATE(YEAR((((HEX2DEC(A3)/60)/60)/24)+DATE(1970,1,1)),11,1)-1)),(((HEX2DEC(A3)/60)/60)/24)+DATE(1970,1,1)+2/24,(((HEX2DEC(A3)/60)/60)/24)+DATE(1970,1,1)+1/24) -> 45281.354 | M3: =IF('tab4'!$B3=0,0,IF('tab4'!$B3=1,1,IF('tab4'!$B3=4,2,IF('tab4'!$B3=5,3,IF('tab4'!$B3=6,4,IF(AND('tab4'!$B3=80,$X$2=2),0,-1)))))) -> 0 | N3: =IF('tab4'!$C3=0,0,IF('tab4'!$C3=1,1,IF('tab4'!$C3=4,2,IF('tab4'!$C3=5,3,IF('tab4'!$C3=6,4,IF(AND('tab4'!$C3=80,$X$2=2),0,-1)))))) -> 0 | O3: =D3 -> 0 | P3: =E3 -> 0 | Q3: =F3 -> 0 | R3: =G3 -> 0 | S3: =IF(HEX2DEC(H3) >= 32768, (HEX2DEC(H3) - 65535 - 1)/10, IF(HEX2DEC(H3) = 32767, IF($X$2=2, S4, 32767), HEX2DEC(H3)/10 )) -> 4.8 | T3: =IF(HEX2DEC(I3) >= 32768, (HEX2DEC(I3) - 65535 - 1)/10, IF(HEX2DEC(I3) = 32767, IF($X$2=2, T4, 32767), HEX2DEC(I3)/10 )) -> 4.5 | U3: =IF(HEX2DEC(J3) >= 32768, (HEX2DEC(J3) - 65535 - 1)/10, IF(HEX2DEC(J3) = 32767, IF($X$2=2, U4, 32767), IF(OR(AND(H3="7fff", I3="7fff", J3="0",$X$2=2),AND(ABS(T3)>2, J3="0",$X$2=2)),U4,HEX2DEC(J3)/10 ))) -> 5.2 | AA3: TSG - temperatury szyny gorącej
A4: 6583e954 | B4: 0 | C4: 0 | D4: 0 | E4: 0 | F4: 0 | G4: 0 | H4: 2f | I4: 2d | J4: 34 | L4: =IF(AND((((HEX2DEC(A4)/60)/60)/24)+DATE(1970,1,1) >= DATE(YEAR((((HEX2DEC(A4)/60)/60)/24)+DATE(1970,1,1)),3,24)+WEEKDAY(DATE(YEAR((((HEX2DEC(A4)/60)/60)/24)+DATE(1970,1,1)),3,31)-1), (((HEX2DEC(A4)/60)/60)/24)+DATE(1970,1,1) < DATE(YEAR((((HEX2DEC(A4)/60)/60)/24)+DATE(1970,1,1)),11,1)+26-WEEKDAY(DATE(YEAR((((HEX2DEC(A4)/60)/60)/24)+DATE(1970,1,1)),11,1)-1)),(((HEX2DEC(A4)/60)/60)/24)+DATE(1970,1,1)+2/24,(((HEX2DEC(A4)/60)/60)/24)+DATE(1970,1,1)+1/24) -> 45281.354 | M4: =IF('tab4'!$B4=0,0,IF('tab4'!$B4=1,1,IF('tab4'!$B4=4,2,IF('tab4'!$B4=5,3,IF('tab4'!$B4=6,4,IF(AND('tab4'!$B4=80,$X$2=2),0,-1)))))) -> 0 | N4: =IF('tab4'!$C4=0,0,IF('tab4'!$C4=1,1,IF('tab4'!$C4=4,2,IF('tab4'!$C4=5,3,IF('tab4'!$C4=6,4,IF(AND('tab4'!$C4=80,$X$2=2),0,-1)))))) -> 0 | O4: =D4 -> 0 | P4: =E4 -> 0 | Q4: =F4 -> 0 | R4: =G4 -> 0 | S4: =IF(HEX2DEC(H4) >= 32768, (HEX2DEC(H4) - 65535 - 1)/10, IF(HEX2DEC(H4) = 32767, IF($X$2=2, S5, 32767), HEX2DEC(H4)/10 )) -> 4.7 | T4: =IF(HEX2DEC(I4) >= 32768, (HEX2DEC(I4) - 65535 - 1)/10, IF(HEX2DEC(I4) = 32767, IF($X$2=2, T5, 32767), HEX2DEC(I4)/10 )) -> 4.5 | U4: =IF(HEX2DEC(J4) >= 32768, (HEX2DEC(J4) - 65535 - 1)/10, IF(HEX2DEC(J4) = 32767, IF($X$2=2, U5, 32767), IF(OR(AND(H4="7fff", I4="7fff", J4="0",$X$2=2),AND(ABS(T4)>2, J4="0",$X$2=2)),U5,HEX2DEC(J4)/10 ))) -> 5.2
A5: 6583e9e4 | B5: 0 | C5: 0 | D5: 0 | E5: 0 | F5: 0 | G5: 0 | H5: 7fff | I5: 7fff | J5: 0 | L5: =IF(AND((((HEX2DEC(A5)/60)/60)/24)+DATE(1970,1,1) >= DATE(YEAR((((HEX2DEC(A5)/60)/60)/24)+DATE(1970,1,1)),3,24)+WEEKDAY(DATE(YEAR((((HEX2DEC(A5)/60)/60)/24)+DATE(1970,1,1)),3,31)-1), (((HEX2DEC(A5)/60)/60)/24)+DATE(1970,1,1) < DATE(YEAR((((HEX2DEC(A5)/60)/60)/24)+DATE(1970,1,1)),11,1)+26-WEEKDAY(DATE(YEAR((((HEX2DEC(A5)/60)/60)/24)+DATE(1970,1,1)),11,1)-1)),(((HEX2DEC(A5)/60)/60)/24)+DATE(1970,1,1)+2/24,(((HEX2DEC(A5)/60)/60)/24)+DATE(1970,1,1)+1/24) -> 45281.355 | M5: =IF('tab4'!$B5=0,0,IF('tab4'!$B5=1,1,IF('tab4'!$B5=4,2,IF('tab4'!$B5=5,3,IF('tab4'!$B5=6,4,IF(AND('tab4'!$B5=80,$X$2=2),0,-1)))))) -> 0 | N5: =IF('tab4'!$C5=0,0,IF('tab4'!$C5=1,1,IF('tab4'!$C5=4,2,IF('tab4'!$C5=5,3,IF('tab4'!$C5=6,4,IF(AND('tab4'!$C5=80,$X$2=2),0,-1)))))) -> 0 | O5: =D5 -> 0 | P5: =E5 -> 0 | Q5: =F5 -> 0 | R5: =G5 -> 0 | S5: =IF(HEX2DEC(H5) >= 32768, (HEX2DEC(H5) - 65535 - 1)/10, IF(HEX2DEC(H5) = 32767, IF($X$2=2, S6, 32767), HEX2DEC(H5)/10 )) -> 4.8 | T5: =IF(HEX2DEC(I5) >= 32768, (HEX2DEC(I5) - 65535 - 1)/10, IF(HEX2DEC(I5) = 32767, IF($X$2=2, T6, 32767), HEX2DEC(I5)/10 )) -> 4.5 | U5: =IF(HEX2DEC(J5) >= 32768, (HEX2DEC(J5) - 65535 - 1)/10, IF(HEX2DEC(J5) = 32767, IF($X$2=2, U6, 32767), IF(OR(AND(H5="7fff", I5="7fff", J5="0",$X$2=2),AND(ABS(T5)>2, J5="0",$X$2=2)),U6,HEX2DEC(J5)/10 ))) -> 5.2
A6: 6583e9e4 | B6: 0 | C6: 0 | D6: 0 | E6: 0 | F6: 0 | G6: 0 | H6: 7fff | I6: 7fff | J6: 34 | L6: =IF(AND((((HEX2DEC(A6)/60)/60)/24)+DATE(1970,1,1) >= DATE(YEAR((((HEX2DEC(A6)/60)/60)/24)+DATE(1970,1,1)),3,24)+WEEKDAY(DATE(YEAR((((HEX2DEC(A6)/60)/60)/24)+DATE(1970,1,1)),3,31)-1), (((HEX2DEC(A6)/60)/60)/24)+DATE(1970,1,1) < DATE(YEAR((((HEX2DEC(A6)/60)/60)/24)+DATE(1970,1,1)),11,1)+26-WEEKDAY(DATE(YEAR((((HEX2DEC(A6)/60)/60)/24)+DATE(1970,1,1)),11,1)-1)),(((HEX2DEC(A6)/60)/60)/24)+DATE(1970,1,1)+2/24,(((HEX2DEC(A6)/60)/60)/24)+DATE(1970,1,1)+1/24) -> 45281.355 | M6: =IF('tab4'!$B6=0,0,IF('tab4'!$B6=1,1,IF('tab4'!$B6=4,2,IF('tab4'!$B6=5,3,IF('tab4'!$B6=6,4,IF(AND('tab4'!$B6=80,$X$2=2),0,-1)))))) -> 0 | N6: =IF('tab4'!$C6=0,0,IF('tab4'!$C6=1,1,IF('tab4'!$C6=4,2,IF('tab4'!$C6=5,3,IF('tab4'!$C6=6,4,IF(AND('tab4'!$C6=80,$X$2=2),0,-1)))))) -> 0 | O6: =D6 -> 0 | P6: =E6 -> 0 | Q6: =F6 -> 0 | R6: =G6 -> 0 | S6: =IF(HEX2DEC(H6) >= 32768, (HEX2DEC(H6) - 65535 - 1)/10, IF(HEX2DEC(H6) = 32767, IF($X$2=2, S7, 32767), HEX2DEC(H6)/10 )) -> 4.8 | T6: =IF(HEX2DEC(I6) >= 32768, (HEX2DEC(I6) - 65535 - 1)/10, IF(HEX2DEC(I6) = 32767, IF($X$2=2, T7, 32767), HEX2DEC(I6)/10 )) -> 4.5 | U6: =IF(HEX2DEC(J6) >= 32768, (HEX2DEC(J6) - 65535 - 1)/10, IF(HEX2DEC(J6) = 32767, IF($X$2=2, U7, 32767), IF(OR(AND(H6="7fff", I6="7fff", J6="0",$X$2=2),AND(ABS(T6)>2, J6="0",$X$2=2)),U7,HEX2DEC(J6)/10 ))) -> 5.2
A7: 6583e9e6 | B7: 0 | C7: 0 | D7: 0 | E7: 0 | F7: 0 | G7: 0 | H7: 30 | I7: 2d | J7: 34 | L7: =IF(AND((((HEX2DEC(A7)/60)/60)/24)+DATE(1970,1,1) >= DATE(YEAR((((HEX2DEC(A7)/60)/60)/24)+DATE(1970,1,1)),3,24)+WEEKDAY(DATE(YEAR((((HEX2DEC(A7)/60)/60)/24)+DATE(1970,1,1)),3,31)-1), (((HEX2DEC(A7)/60)/60)/24)+DATE(1970,1,1) < DATE(YEAR((((HEX2DEC(A7)/60)/60)/24)+DATE(1970,1,1)),11,1)+26-WEEKDAY(DATE(YEAR((((HEX2DEC(A7)/60)/60)/24)+DATE(1970,1,1)),11,1)-1)),(((HEX2DEC(A7)/60)/60)/24)+DATE(1970,1,1)+2/24,(((HEX2DEC(A7)/60)/60)/24)+DATE(1970,1,1)+1/24) -> 45281.355 | M7: =IF('tab4'!$B7=0,0,IF('tab4'!$B7=1,1,IF('tab4'!$B7=4,2,IF('tab4'!$B7=5,3,IF('tab4'!$B7=6,4,IF(AND('tab4'!$B7=80,$X$2=2),0,-1)))))) -> 0 | N7: =IF('tab4'!$C7=0,0,IF('tab4'!$C7=1,1,IF('tab4'!$C7=4,2,IF('tab4'!$C7=5,3,IF('tab4'!$C7=6,4,IF(AND('tab4'!$C7=80,$X$2=2),0,-1)))))) -> 0 | O7: =D7 -> 0 | P7: =E7 -> 0 | Q7: =F7 -> 0 | R7: =G7 -> 0 | S7: =IF(HEX2DEC(H7) >= 32768, (HEX2DEC(H7) - 65535 - 1)/10, IF(HEX2DEC(H7) = 32767, IF($X$2=2, S8, 32767), HEX2DEC(H7)/10 )) -> 4.8 | T7: =IF(HEX2DEC(I7) >= 32768, (HEX2DEC(I7) - 65535 - 1)/10, IF(HEX2DEC(I7) = 32767, IF($X$2=2, T8, 32767), HEX2DEC(I7)/10 )) -> 4.5 | U7: =IF(HEX2DEC(J7) >= 32768, (HEX2DEC(J7) - 65535 - 1)/10, IF(HEX2DEC(J7) = 32767, IF($X$2=2, U8, 32767), IF(OR(AND(H7="7fff", I7="7fff", J7="0",$X$2=2),AND(ABS(T7)>2, J7="0",$X$2=2)),U8,HEX2DEC(J7)/10 ))) -> 5.2
A8: 6583e9e7 | B8: 0 | C8: 0 | D8: 0 | E8: 0 | F8: 0 | G8: 0 | H8: 30 | I8: 2d | J8: 34 | L8: =IF(AND((((HEX2DEC(A8)/60)/60)/24)+DATE(1970,1,1) >= DATE(YEAR((((HEX2DEC(A8)/60)/60)/24)+DATE(1970,1,1)),3,24)+WEEKDAY(DATE(YEAR((((HEX2DEC(A8)/60)/60)/24)+DATE(1970,1,1)),3,31)-1), (((HEX2DEC(A8)/60)/60)/24)+DATE(1970,1,1) < DATE(YEAR((((HEX2DEC(A8)/60)/60)/24)+DATE(1970,1,1)),11,1)+26-WEEKDAY(DATE(YEAR((((HEX2DEC(A8)/60)/60)/24)+DATE(1970,1,1)),11,1)-1)),(((HEX2DEC(A8)/60)/60)/24)+DATE(1970,1,1)+2/24,(((HEX2DEC(A8)/60)/60)/24)+DATE(1970,1,1)+1/24) -> 45281.355 | M8: =IF('tab4'!$B8=0,0,IF('tab4'!$B8=1,1,IF('tab4'!$B8=4,2,IF('tab4'!$B8=5,3,IF('tab4'!$B8=6,4,IF(AND('tab4'!$B8=80,$X$2=2),0,-1)))))) -> 0 | N8: =IF('tab4'!$C8=0,0,IF('tab4'!$C8=1,1,IF('tab4'!$C8=4,2,IF('tab4'!$C8=5,3,IF('tab4'!$C8=6,4,IF(AND('tab4'!$C8=80,$X$2=2),0,-1)))))) -> 0 | O8: =D8 -> 0 | P8: =E8 -> 0 | Q8: =F8 -> 0 | R8: =G8 -> 0 | S8: =IF(HEX2DEC(H8) >= 32768, (HEX2DEC(H8) - 65535 - 1)/10, IF(HEX2DEC(H8) = 32767, IF($X$2=2, S9, 32767), HEX2DEC(H8)/10 )) -> 4.8 | T8: =IF(HEX2DEC(I8) >= 32768, (HEX2DEC(I8) - 65535 - 1)/10, IF(HEX2DEC(I8) = 32767, IF($X$2=2, T9, 32767), HEX2DEC(I8)/10 )) -> 4.5 | U8: =IF(HEX2DEC(J8) >= 32768, (HEX2DEC(J8) - 65535 - 1)/10, IF(HEX2DEC(J8) = 32767, IF($X$2=2, U9, 32767), IF(OR(AND(H8="7fff", I8="7fff", J8="0",$X$2=2),AND(ABS(T8)>2, J8="0",$X$2=2)),U9,HEX2DEC(J8)/10 ))) -> 5.2
A9: 6583f965 | B9: 0 | C9: 0 | D9: 0 | E9: 0 | F9: 0 | G9: 1 | H9: 37 | I9: 35 | J9: 3d | L9: =IF(AND((((HEX2DEC(A9)/60)/60)/24)+DATE(1970,1,1) >= DATE(YEAR((((HEX2DEC(A9)/60)/60)/24)+DATE(1970,1,1)),3,24)+WEEKDAY(DATE(YEAR((((HEX2DEC(A9)/60)/60)/24)+DATE(1970,1,1)),3,31)-1), (((HEX2DEC(A9)/60)/60)/24)+DATE(1970,1,1) < DATE(YEAR((((HEX2DEC(A9)/60)/60)/24)+DATE(1970,1,1)),11,1)+26-WEEKDAY(DATE(YEAR((((HEX2DEC(A9)/60)/60)/24)+DATE(1970,1,1)),11,1)-1)),(((HEX2DEC(A9)/60)/60)/24)+DATE(1970,1,1)+2/24,(((HEX2DEC(A9)/60)/60)/24)+DATE(1970,1,1)+1/24) -> 45281.401 | M9: =IF('tab4'!$B9=0,0,IF('tab4'!$B9=1,1,IF('tab4'!$B9=4,2,IF('tab4'!$B9=5,3,IF('tab4'!$B9=6,4,IF(AND('tab4'!$B9=80,$X$2=2),0,-1)))))) -> 0 | N9: =IF('tab4'!$C9=0,0,IF('tab4'!$C9=1,1,IF('tab4'!$C9=4,2,IF('tab4'!$C9=5,3,IF('tab4'!$C9=6,4,IF(AND('tab4'!$C9=80,$X$2=2),0,-1)))))) -> 0 | O9: =D9 -> 0 | P9: =E9 -> 0 | Q9: =F9 -> 0 | R9: =G9 -> 1 | S9: =IF(HEX2DEC(H9) >= 32768, (HEX2DEC(H9) - 65535 - 1)/10, IF(HEX2DEC(H9) = 32767, IF($X$2=2, S10, 32767), HEX2DEC(H9)/10 )) -> 5.5 | T9: =IF(HEX2DEC(I9) >= 32768, (HEX2DEC(I9) - 65535 - 1)/10, IF(HEX2DEC(I9) = 32767, IF($X$2=2, T10, 32767), HEX2DEC(I9)/10 )) -> 5.3 | U9: =IF(HEX2DEC(J9) >= 32768, (HEX2DEC(J9) - 65535 - 1)/10, IF(HEX2DEC(J9) = 32767, IF($X$2=2, U10, 32767), IF(OR(AND(H9="7fff", I9="7fff", J9="0",$X$2=2),AND(ABS(T9)>2, J9="0",$X$2=2)),U10,HEX2DEC(J9)/10 ))) -> 6.1
A10: 6583feef | B10: 0 | C10: 0 | D10: 0 | E10: 0 | F10: 0 | G10: 0 | H10: 39 | I10: 37 | J10: 3c | L10: =IF(AND((((HEX2DEC(A10)/60)/60)/24)+DATE(1970,1,1) >= DATE(YEAR((((HEX2DEC(A10)/60)/60)/24)+DATE(1970,1,1)),3,24)+WEEKDAY(DATE(YEAR((((HEX2DEC(A10)/60)/60)/24)+DATE(1970,1,1)),3,31)-1), (((HEX2DEC(A10)/60)/60)/24)+DATE(1970,1,1) < DATE(YEAR((((HEX2DEC(A10)/60)/60)/24)+DATE(1970,1,1)),11,1)+26-WEEKDAY(DATE(YEAR((((HEX2DEC(A10)/60)/60)/24)+DATE(1970,1,1)),11,1)-1)),(((HEX2DEC(A10)/60)/60)/24)+DATE(1970,1,1)+2/24,(((HEX2DEC(A10)/60)/60)/24)+DATE(1970,1,1)+1/24) -> 45281.418 | M10: =IF('tab4'!$B10=0,0,IF('tab4'!$B10=1,1,IF('tab4'!$B10=4,2,IF('tab4'!$B10=5,3,IF('tab4'!$B10=6,4,IF(AND('tab4'!$B10=80,$X$2=2),0,-1)))))) -> 0 | N10: =IF('tab4'!$C10=0,0,IF('tab4'!$C10=1,1,IF('tab4'!$C10=4,2,IF('tab4'!$C10=5,3,IF('tab4'!$C10=6,4,IF(AND('tab4'!$C10=80,$X$2=2),0,-1)))))) -> 0 | O10: =D10 -> 0 | P10: =E10 -> 0 | Q10: =F10 -> 0 | R10: =G10 -> 0 | S10: =IF(HEX2DEC(H10) >= 32768, (HEX2DEC(H10) - 65535 - 1)/10, IF(HEX2DEC(H10) = 32767, IF($X$2=2, S11, 32767), HEX2DEC(H10)/10 )) -> 5.7 | T10: =IF(HEX2DEC(I10) >= 32768, (HEX2DEC(I10) - 65535 - 1)/10, IF(HEX2DEC(I10) = 32767, IF($X$2=2, T11, 32767), HEX2DEC(I10)/10 )) -> 5.5 | U10: =IF(HEX2DEC(J10) >= 32768, (HEX2DEC(J10) - 65535 - 1)/10, IF(HEX2DEC(J10) = 32767, IF($X$2=2, U11, 32767), IF(OR(AND(H10="7fff", I10="7fff", J10="0",$X$2=2),AND(ABS(T10)>2, J10="0",$X$2=2)),U11,HEX2DEC(J10)/10 ))) -> 6
A11: 658405ca | B11: 0 | C11: 0 | D11: 0 | E11: 0 | F11: 0 | G11: 1 | H11: 3b | I11: 39 | J11: 3b | L11: =IF(AND((((HEX2DEC(A11)/60)/60)/24)+DATE(1970,1,1) >= DATE(YEAR((((HEX2DEC(A11)/60)/60)/24)+DATE(1970,1,1)),3,24)+WEEKDAY(DATE(YEAR((((HEX2DEC(A11)/60)/60)/24)+DATE(1970,1,1)),3,31)-1), (((HEX2DEC(A11)/60)/60)/24)+DATE(1970,1,1) < DATE(YEAR((((HEX2DEC(A11)/60)/60)/24)+DATE(1970,1,1)),11,1)+26-WEEKDAY(DATE(YEAR((((HEX2DEC(A11)/60)/60)/24)+DATE(1970,1,1)),11,1)-1)),(((HEX2DEC(A11)/60)/60)/24)+DATE(1970,1,1)+2/24,(((HEX2DEC(A11)/60)/60)/24)+DATE(1970,1,1)+1/24) -> 45281.438 | M11: =IF('tab4'!$B11=0,0,IF('tab4'!$B11=1,1,IF('tab4'!$B11=4,2,IF('tab4'!$B11=5,3,IF('tab4'!$B11=6,4,IF(AND('tab4'!$B11=80,$X$2=2),0,-1)))))) -> 0 | N11: =IF('tab4'!$C11=0,0,IF('tab4'!$C11=1,1,IF('tab4'!$C11=4,2,IF('tab4'!$C11=5,3,IF('tab4'!$C11=6,4,IF(AND('tab4'!$C11=80,$X$2=2),0,-1)))))) -> 0 | O11: =D11 -> 0 | P11: =E11 -> 0 | Q11: =F11 -> 0 | R11: =G11 -> 1 | S11: =IF(HEX2DEC(H11) >= 32768, (HEX2DEC(H11) - 65535 - 1)/10, IF(HEX2DEC(H11) = 32767, IF($X$2=2, S12, 32767), HEX2DEC(H11)/10 )) -> 5.9 | T11: =IF(HEX2DEC(I11) >= 32768, (HEX2DEC(I11) - 65535 - 1)/10, IF(HEX2DEC(I11) = 32767, IF($X$2=2, T12, 32767), HEX2DEC(I11)/10 )) -> 5.7 | U11: =IF(HEX2DEC(J11) >= 32768, (HEX2DEC(J11) - 65535 - 1)/10, IF(HEX2DEC(J11) = 32767, IF($X$2=2, U12, 32767), IF(OR(AND(H11="7fff", I11="7fff", J11="0",$X$2=2),AND(ABS(T11)>2, J11="0",$X$2=2)),U12,HEX2DEC(J11)/10 ))) -> 5.9
A12: 65841eb7 | B12: 0 | C12: 0 | D12: 0 | E12: 0 | F12: 0 | G12: 0 | H12: 3c | I12: 38 | J12: 3b | L12: =IF(AND((((HEX2DEC(A12)/60)/60)/24)+DATE(1970,1,1) >= DATE(YEAR((((HEX2DEC(A12)/60)/60)/24)+DATE(1970,1,1)),3,24)+WEEKDAY(DATE(YEAR((((HEX2DEC(A12)/60)/60)/24)+DATE(1970,1,1)),3,31)-1), (((HEX2DEC(A12)/60)/60)/24)+DATE(1970,1,1) < DATE(YEAR((((HEX2DEC(A12)/60)/60)/24)+DATE(1970,1,1)),11,1)+26-WEEKDAY(DATE(YEAR((((HEX2DEC(A12)/60)/60)/24)+DATE(1970,1,1)),11,1)-1)),(((HEX2DEC(A12)/60)/60)/24)+DATE(1970,1,1)+2/24,(((HEX2DEC(A12)/60)/60)/24)+DATE(1970,1,1)+1/24) -> 45281.512 | M12: =IF('tab4'!$B12=0,0,IF('tab4'!$B12=1,1,IF('tab4'!$B12=4,2,IF('tab4'!$B12=5,3,IF('tab4'!$B12=6,4,IF(AND('tab4'!$B12=80,$X$2=2),0,-1)))))) -> 0 | N12: =IF('tab4'!$C12=0,0,IF('tab4'!$C12=1,1,IF('tab4'!$C12=4,2,IF('tab4'!$C12=5,3,IF('tab4'!$C12=6,4,IF(AND('tab4'!$C12=80,$X$2=2),0,-1)))))) -> 0 | O12: =D12 -> 0 | P12: =E12 -> 0 | Q12: =F12 -> 0 | R12: =G12 -> 0 | S12: =IF(HEX2DEC(H12) >= 32768, (HEX2DEC(H12) - 65535 - 1)/10, IF(HEX2DEC(H12) = 32767, IF($X$2=2, S13, 32767), HEX2DEC(H12)/10 )) -> 6 | T12: =IF(HEX2DEC(I12) >= 32768, (HEX2DEC(I12) - 65535 - 1)/10, IF(HEX2DEC(I12) = 32767, IF($X$2=2, T13, 32767), HEX2DEC(I12)/10 )) -> 5.6 | U12: =IF(HEX2DEC(J12) >= 32768, (HEX2DEC(J12) - 65535 - 1)/10, IF(HEX2DEC(J12) = 32767, IF($X$2=2, U13, 32767), IF(OR(AND(H12="7fff", I12="7fff", J12="0",$X$2=2),AND(ABS(T12)>2, J12="0",$X$2=2)),U13,HEX2DEC(J12)/10 ))) -> 5.9
A13: 65841ef1 | B13: 0 | C13: 0 | D13: 0 | E13: 0 | F13: 0 | G13: 1 | H13: 3c | I13: 38 | J13: 3c | L13: =IF(AND((((HEX2DEC(A13)/60)/60)/24)+DATE(1970,1,1) >= DATE(YEAR((((HEX2DEC(A13)/60)/60)/24)+DATE(1970,1,1)),3,24)+WEEKDAY(DATE(YEAR((((HEX2DEC(A13)/60)/60)/24)+DATE(1970,1,1)),3,31)-1), (((HEX2DEC(A13)/60)/60)/24)+DATE(1970,1,1) < DATE(YEAR((((HEX2DEC(A13)/60)/60)/24)+DATE(1970,1,1)),11,1)+26-WEEKDAY(DATE(YEAR((((HEX2DEC(A13)/60)/60)/24)+DATE(1970,1,1)),11,1)-1)),(((HEX2DEC(A13)/60)/60)/24)+DATE(1970,1,1)+2/24,(((HEX2DEC(A13)/60)/60)/24)+DATE(1970,1,1)+1/24) -> 45281.513 | M13: =IF('tab4'!$B13=0,0,IF('tab4'!$B13=1,1,IF('tab4'!$B13=4,2,IF('tab4'!$B13=5,3,IF('tab4'!$B13=6,4,IF(AND('tab4'!$B13=80,$X$2=2),0,-1)))))) -> 0 | N13: =IF('tab4'!$C13=0,0,IF('tab4'!$C13=1,1,IF('tab4'!$C13=4,2,IF('tab4'!$C13=5,3,IF('tab4'!$C13=6,4,IF(AND('tab4'!$C13=80,$X$2=2),0,-1)))))) -> 0 | O13: =D13 -> 0 | P13: =E13 -> 0 | Q13: =F13 -> 0 | R13: =G13 -> 1 | S13: =IF(HEX2DEC(H13) >= 32768, (HEX2DEC(H13) - 65535 - 1)/10, IF(HEX2DEC(H13) = 32767, IF($X$2=2, S14, 32767), HEX2DEC(H13)/10 )) -> 6 | T13: =IF(HEX2DEC(I13) >= 32768, (HEX2DEC(I13) - 65535 - 1)/10, IF(HEX2DEC(I13) = 32767, IF($X$2=2, T14, 32767), HEX2DEC(I13)/10 )) -> 5.6 | U13: =IF(HEX2DEC(J13) >= 32768, (HEX2DEC(J13) - 65535 - 1)/10, IF(HEX2DEC(J13) = 32767, IF($X$2=2, U14, 32767), IF(OR(AND(H13="7fff", I13="7fff", J13="0",$X$2=2),AND(ABS(T13)>2, J13="0",$X$2=2)),U14,HEX2DEC(J13)/10 ))) -> 6
A14: 65843b11 | B14: 0 | C14: 0 | D14: 0 | E14: 0 | F14: 0 | G14: 1 | H14: 3e | I14: 39 | J14: 3d | L14: =IF(AND((((HEX2DEC(A14)/60)/60)/24)+DATE(1970,1,1) >= DATE(YEAR((((HEX2DEC(A14)/60)/60)/24)+DATE(1970,1,1)),3,24)+WEEKDAY(DATE(YEAR((((HEX2DEC(A14)/60)/60)/24)+DATE(1970,1,1)),3,31)-1), (((HEX2DEC(A14)/60)/60)/24)+DATE(1970,1,1) < DATE(YEAR((((HEX2DEC(A14)/60)/60)/24)+DATE(1970,1,1)),11,1)+26-WEEKDAY(DATE(YEAR((((HEX2DEC(A14)/60)/60)/24)+DATE(1970,1,1)),11,1)-1)),(((HEX2DEC(A14)/60)/60)/24)+DATE(1970,1,1)+2/24,(((HEX2DEC(A14)/60)/60)/24)+DATE(1970,1,1)+1/24) -> 45281.596 | M14: =IF('tab4'!$B14=0,0,IF('tab4'!$B14=1,1,IF('tab4'!$B14=4,2,IF('tab4'!$B14=5,3,IF('tab4'!$B14=6,4,IF(AND('tab4'!$B14=80,$X$2=2),0,-1)))))) -> 0 | N14: =IF('tab4'!$C14=0,0,IF('tab4'!$C14=1,1,IF('tab4'!$C14=4,2,IF('tab4'!$C14=5,3,IF('tab4'!$C14=6,4,IF(AND('tab4'!$C14=80,$X$2=2),0,-1)))))) -> 0 | O14: =D14 -> 0 | P14: =E14 -> 0 | Q14: =F14 -> 0 | R14: =G14 -> 1 | S14: =IF(HEX2DEC(H14) >= 32768, (HEX2DEC(H14) - 65535 - 1)/10, IF(HEX2DEC(H14) = 32767, IF($X$2=2, S15, 32767), HEX2DEC(H14)/10 )) -> 6.2 | T14: =IF(HEX2DEC(I14) >= 32768, (HEX2DEC(I14) - 65535 - 1)/10, IF(HEX2DEC(I14) = 32767, IF($X$2=2, T15, 32767), HEX2DEC(I14)/10 )) -> 5.7 | U14: =IF(HEX2DEC(J14) >= 32768, (HEX2DEC(J14) - 65535 - 1)/10, IF(HEX2DEC(J14) = 32767, IF($X$2=2, U15, 32767), IF(OR(AND(H14="7fff", I14="7fff", J14="0",$X$2=2),AND(ABS(T14)>2, J14="0",$X$2=2)),U15,HEX2DEC(J14)/10 ))) -> 6.1
A15: 65844c1c | B15: 0 | C15: 0 | D15: 0 | E15: 0 | F15: 0 | G15: 0 | H15: 3d | I15: 38 | J15: 40 | L15: =IF(AND((((HEX2DEC(A15)/60)/60)/24)+DATE(1970,1,1) >= DATE(YEAR((((HEX2DEC(A15)/60)/60)/24)+DATE(1970,1,1)),3,24)+WEEKDAY(DATE(YEAR((((HEX2DEC(A15)/60)/60)/24)+DATE(1970,1,1)),3,31)-1), (((HEX2DEC(A15)/60)/60)/24)+DATE(1970,1,1) < DATE(YEAR((((HEX2DEC(A15)/60)/60)/24)+DATE(1970,1,1)),11,1)+26-WEEKDAY(DATE(YEAR((((HEX2DEC(A15)/60)/60)/24)+DATE(1970,1,1)),11,1)-1)),(((HEX2DEC(A15)/60)/60)/24)+DATE(1970,1,1)+2/24,(((HEX2DEC(A15)/60)/60)/24)+DATE(1970,1,1)+1/24) -> 45281.646 | M15: =IF('tab4'!$B15=0,0,IF('tab4'!$B15=1,1,IF('tab4'!$B15=4,2,IF('tab4'!$B15=5,3,IF('tab4'!$B15=6,4,IF(AND('tab4'!$B15=80,$X$2=2),0,-1)))))) -> 0 | N15: =IF('tab4'!$C15=0,0,IF('tab4'!$C15=1,1,IF('tab4'!$C15=4,2,IF('tab4'!$C15=5,3,IF('tab4'!$C15=6,4,IF(AND('tab4'!$C15=80,$X$2=2),0,-1)))))) -> 0 | O15: =D15 -> 0 | P15: =E15 -> 0 | Q15: =F15 -> 0 | R15: =G15 -> 0 | S15: =IF(HEX2DEC(H15) >= 32768, (HEX2DEC(H15) - 65535 - 1)/10, IF(HEX2DEC(H15) = 32767, IF($X$2=2, S16, 32767), HEX2DEC(H15)/10 )) -> 6.1 | T15: =IF(HEX2DEC(I15) >= 32768, (HEX2DEC(I15) - 65535 - 1)/10, IF(HEX2DEC(I15) = 32767, IF($X$2=2, T16, 32767), HEX2DEC(I15)/10 )) -> 5.6 | U15: =IF(HEX2DEC(J15) >= 32768, (HEX2DEC(J15) - 65535 - 1)/10, IF(HEX2DEC(J15) = 32767, IF($X$2=2, U16, 32767), IF(OR(AND(H15="7fff", I15="7fff", J15="0",$X$2=2),AND(ABS(T15)>2, J15="0",$X$2=2)),U16,HEX2DEC(J15)/10 ))) -> 6.4
... A1147: 65b8846f | B1147: 0 | C1147: 4 | D1147: 0 | E1147: 1 | F1147: 0 | G1147: 0 | H1147: ffe4 | I1147: ffd8 | J1147: ffe2 | L1147: =IF(AND((((HEX2DEC(A1147)/60)/60)/24)+DATE(1970,1,1) >= DATE(YEAR((((HEX2DEC(A1147)/60)/60)/24)+DATE(1970,1,1)),3,24)+WEEKDAY(DATE(YEAR((((HEX2DEC(A1147)/60)/60)/24)+DATE(1970,1,1)),3,31)-1), (((HEX2DEC(A1147)/60)/60)/24)+DATE(1970,1,1) < DATE(YEAR((((HEX2DEC(A1147)/60)/60)/24)+DATE(1970,1,1)),11,1)+26-WEEKDAY(DATE(YEAR((((HEX2DEC(A1147)/60)/60)/24)+DATE(1970,1,1)),11,1)-1)),(((HEX2DEC(A1147)/60)/60)/24)+DATE(1970,1,1)+2/24,(((HEX2DEC(A1147)/60)/60)/24)+DATE(1970,1,1)+1/24) -> 45321.256 | M1147: =IF('tab4'!$B1147=0,0,IF('tab4'!$B1147=1,1,IF('tab4'!$B1147=4,2,IF('tab4'!$B1147=5,3,IF('tab4'!$B1147=6,4,IF(AND('tab4'!$B1147=80,$X$2=2),0,-1)))))) -> 0 | N1147: =IF('tab4'!$C1147=0,0,IF('tab4'!$C1147=1,1,IF('tab4'!$C1147=4,2,IF('tab4'!$C1147=5,3,IF('tab4'!$C1147=6,4,IF(AND('tab4'!$C1147=80,$X$2=2),0,-1)))))) -> 2 | O1147: =D1147 -> 0 | P1147: =E1147 -> 1 | Q1147: =F1147 -> 0 | R1147: =G1147 -> 0 | S1147: =IF(HEX2DEC(H1147) >= 32768, (HEX2DEC(H1147) - 65535 - 1)/10, IF(HEX2DEC(H1147) = 32767, IF($X$2=2, S1148, 32767), HEX2DEC(H1147)/10 )) -> -2.8 | T1147: =IF(HEX2DEC(I1147) >= 32768, (HEX2DEC(I1147) - 65535 - 1)/10, IF(HEX2DEC(I1147) = 32767, IF($X$2=2, T1148, 32767), HEX2DEC(I1147)/10 )) -> -4 | U1147: =IF(HEX2DEC(J1147) >= 32768, (HEX2DEC(J1147) - 65535 - 1)/10, IF(HEX2DEC(J1147) = 32767, IF($X$2=2, U1148, 32767), IF(OR(AND(H1147="7fff", I1147="7fff", J1147="0",$X$2=2),AND(ABS(T1147)>2, J1147="0",$X$2=2)),U1148,HEX2DEC(J1147)/10 ))) -> -3
A1148: 65b8a090 | B1148: 0 | C1148: 4 | D1148: 0 | E1148: 1 | F1148: 0 | G1148: 0 | H1148: ffe4 | I1148: ffda | J1148: 9 | L1148: =IF(AND((((HEX2DEC(A1148)/60)/60)/24)+DATE(1970,1,1) >= DATE(YEAR((((HEX2DEC(A1148)/60)/60)/24)+DATE(1970,1,1)),3,24)+WEEKDAY(DATE(YEAR((((HEX2DEC(A1148)/60)/60)/24)+DATE(1970,1,1)),3,31)-1), (((HEX2DEC(A1148)/60)/60)/24)+DATE(1970,1,1) < DATE(YEAR((((HEX2DEC(A1148)/60)/60)/24)+DATE(1970,1,1)),11,1)+26-WEEKDAY(DATE(YEAR((((HEX2DEC(A1148)/60)/60)/24)+DATE(1970,1,1)),11,1)-1)),(((HEX2DEC(A1148)/60)/60)/24)+DATE(1970,1,1)+2/24,(((HEX2DEC(A1148)/60)/60)/24)+DATE(1970,1,1)+1/24) -> 45321.34 | M1148: =IF('tab4'!$B1148=0,0,IF('tab4'!$B1148=1,1,IF('tab4'!$B1148=4,2,IF('tab4'!$B1148=5,3,IF('tab4'!$B1148=6,4,IF(AND('tab4'!$B1148=80,$X$2=2),0,-1)))))) -> 0 | N1148: =IF('tab4'!$C1148=0,0,IF('tab4'!$C1148=1,1,IF('tab4'!$C1148=4,2,IF('tab4'!$C1148=5,3,IF('tab4'!$C1148=6,4,IF(AND('tab4'!$C1148=80,$X$2=2),0,-1)))))) -> 2 | O1148: =D1148 -> 0 | P1148: =E1148 -> 1 | Q1148: =F1148 -> 0 | R1148: =G1148 -> 0 | S1148: =IF(HEX2DEC(H1148) >= 32768, (HEX2DEC(H1148) - 65535 - 1)/10, IF(HEX2DEC(H1148) = 32767, IF($X$2=2, S1149, 32767), HEX2DEC(H1148)/10 )) -> -2.8 | T1148: =IF(HEX2DEC(I1148) >= 32768, (HEX2DEC(I1148) - 65535 - 1)/10, IF(HEX2DEC(I1148) = 32767, IF($X$2=2, T1149, 32767), HEX2DEC(I1148)/10 )) -> -3.8 | U1148: =IF(HEX2DEC(J1148) >= 32768, (HEX2DEC(J1148) - 65535 - 1)/10, IF(HEX2DEC(J1148) = 32767, IF($X$2=2, U1149, 32767), IF(OR(AND(H1148="7fff", I1148="7fff", J1148="0",$X$2=2),AND(ABS(T1148)>2, J1148="0",$X$2=2)),U1149,HEX2DEC(J1148)/10 ))) -> 0.9
A1149: 65b8b34e | B1149: 0 | C1149: 0 | D1149: 0 | E1149: 0 | F1149: 0 | G1149: 0 | H1149: 9 | I1149: 29 | J1149: 56 | L1149: =IF(AND((((HEX2DEC(A1149)/60)/60)/24)+DATE(1970,1,1) >= DATE(YEAR((((HEX2DEC(A1149)/60)/60)/24)+DATE(1970,1,1)),3,24)+WEEKDAY(DATE(YEAR((((HEX2DEC(A1149)/60)/60)/24)+DATE(1970,1,1)),3,31)-1), (((HEX2DEC(A1149)/60)/60)/24)+DATE(1970,1,1) < DATE(YEAR((((HEX2DEC(A1149)/60)/60)/24)+DATE(1970,1,1)),11,1)+26-WEEKDAY(DATE(YEAR((((HEX2DEC(A1149)/60)/60)/24)+DATE(1970,1,1)),11,1)-1)),(((HEX2DEC(A1149)/60)/60)/24)+DATE(1970,1,1)+2/24,(((HEX2DEC(A1149)/60)/60)/24)+DATE(1970,1,1)+1/24) -> 45321.395 | M1149: =IF('tab4'!$B1149=0,0,IF('tab4'!$B1149=1,1,IF('tab4'!$B1149=4,2,IF('tab4'!$B1149=5,3,IF('tab4'!$B1149=6,4,IF(AND('tab4'!$B1149=80,$X$2=2),0,-1)))))) -> 0 | N1149: =IF('tab4'!$C1149=0,0,IF('tab4'!$C1149=1,1,IF('tab4'!$C1149=4,2,IF('tab4'!$C1149=5,3,IF('tab4'!$C1149=6,4,IF(AND('tab4'!$C1149=80,$X$2=2),0,-1)))))) -> 0 | O1149: =D1149 -> 0 | P1149: =E1149 -> 0 | Q1149: =F1149 -> 0 | R1149: =G1149 -> 0 | S1149: =IF(HEX2DEC(H1149) >= 32768, (HEX2DEC(H1149) - 65535 - 1)/10, IF(HEX2DEC(H1149) = 32767, IF($X$2=2, S1150, 32767), HEX2DEC(H1149)/10 )) -> 0.9 | T1149: =IF(HEX2DEC(I1149) >= 32768, (HEX2DEC(I1149) - 65535 - 1)/10, IF(HEX2DEC(I1149) = 32767, IF($X$2=2, T1150, 32767), HEX2DEC(I1149)/10 )) -> 4.1 | U1149: =IF(HEX2DEC(J1149) >= 32768, (HEX2DEC(J1149) - 65535 - 1)/10, IF(HEX2DEC(J1149) = 32767, IF($X$2=2, U1150, 32767), IF(OR(AND(H1149="7fff", I1149="7fff", J1149="0",$X$2=2),AND(ABS(T1149)>2, J1149="0",$X$2=2)),U1150,HEX2DEC(J1149)/10 ))) -> 8.6
A1150: 65b8cf6e | B1150: 0 | C1150: 0 | D1150: 0 | E1150: 0 | F1150: 0 | G1150: 0 | H1150: 58 | I1150: b0 | J1150: 8a | L1150: =IF(AND((((HEX2DEC(A1150)/60)/60)/24)+DATE(1970,1,1) >= DATE(YEAR((((HEX2DEC(A1150)/60)/60)/24)+DATE(1970,1,1)),3,24)+WEEKDAY(DATE(YEAR((((HEX2DEC(A1150)/60)/60)/24)+DATE(1970,1,1)),3,31)-1), (((HEX2DEC(A1150)/60)/60)/24)+DATE(1970,1,1) < DATE(YEAR((((HEX2DEC(A1150)/60)/60)/24)+DATE(1970,1,1)),11,1)+26-WEEKDAY(DATE(YEAR((((HEX2DEC(A1150)/60)/60)/24)+DATE(1970,1,1)),11,1)-1)),(((HEX2DEC(A1150)/60)/60)/24)+DATE(1970,1,1)+2/24,(((HEX2DEC(A1150)/60)/60)/24)+DATE(1970,1,1)+1/24) -> 45321.478 | M1150: =IF('tab4'!$B1150=0,0,IF('tab4'!$B1150=1,1,IF('tab4'!$B1150=4,2,IF('tab4'!$B1150=5,3,IF('tab4'!$B1150=6,4,IF(AND('tab4'!$B1150=80,$X$2=2),0,-1)))))) -> 0 | N1150: =IF('tab4'!$C1150=0,0,IF('tab4'!$C1150=1,1,IF('tab4'!$C1150=4,2,IF('tab4'!$C1150=5,3,IF('tab4'!$C1150=6,4,IF(AND('tab4'!$C1150=80,$X$2=2),0,-1)))))) -> 0 | O1150: =D1150 -> 0 | P1150: =E1150 -> 0 | Q1150: =F1150 -> 0 | R1150: =G1150 -> 0 | S1150: =IF(HEX2DEC(H1150) >= 32768, (HEX2DEC(H1150) - 65535 - 1)/10, IF(HEX2DEC(H1150) = 32767, IF($X$2=2, S1151, 32767), HEX2DEC(H1150)/10 )) -> 8.8 | T1150: =IF(HEX2DEC(I1150) >= 32768, (HEX2DEC(I1150) - 65535 - 1)/10, IF(HEX2DEC(I1150) = 32767, IF($X$2=2, T1151, 32767), HEX2DEC(I1150)/10 )) -> 17.6 | U1150: =IF(HEX2DEC(J1150) >= 32768, (HEX2DEC(J1150) - 65535 - 1)/10, IF(HEX2DEC(J1150) = 32767, IF($X$2=2, U1151, 32767), IF(OR(AND(H1150="7fff", I1150="7fff", J1150="0",$X$2=2),AND(ABS(T1150)>2, J1150="0",$X$2=2)),U1151,HEX2DEC(J1150)/10 ))) -> 13.8
A1151: 65b8eb8e | B1151: 0 | C1151: 0 | D1151: 0 | E1151: 0 | F1151: 0 | G1151: 0 | H1151: 80 | I1151: bd | J1151: 7a | L1151: =IF(AND((((HEX2DEC(A1151)/60)/60)/24)+DATE(1970,1,1) >= DATE(YEAR((((HEX2DEC(A1151)/60)/60)/24)+DATE(1970,1,1)),3,24)+WEEKDAY(DATE(YEAR((((HEX2DEC(A1151)/60)/60)/24)+DATE(1970,1,1)),3,31)-1), (((HEX2DEC(A1151)/60)/60)/24)+DATE(1970,1,1) < DATE(YEAR((((HEX2DEC(A1151)/60)/60)/24)+DATE(1970,1,1)),11,1)+26-WEEKDAY(DATE(YEAR((((HEX2DEC(A1151)/60)/60)/24)+DATE(1970,1,1)),11,1)-1)),(((HEX2DEC(A1151)/60)/60)/24)+DATE(1970,1,1)+2/24,(((HEX2DEC(A1151)/60)/60)/24)+DATE(1970,1,1)+1/24) -> 45321.562 | M1151: =IF('tab4'!$B1151=0,0,IF('tab4'!$B1151=1,1,IF('tab4'!$B1151=4,2,IF('tab4'!$B1151=5,3,IF('tab4'!$B1151=6,4,IF(AND('tab4'!$B1151=80,$X$2=2),0,-1)))))) -> 0 | N1151: =IF('tab4'!$C1151=0,0,IF('tab4'!$C1151=1,1,IF('tab4'!$C1151=4,2,IF('tab4'!$C1151=5,3,IF('tab4'!$C1151=6,4,IF(AND('tab4'!$C1151=80,$X$2=2),0,-1)))))) -> 0 | O1151: =D1151 -> 0 | P1151: =E1151 -> 0 | Q1151: =F1151 -> 0 | R1151: =G1151 -> 0 | S1151: =IF(HEX2DEC(H1151) >= 32768, (HEX2DEC(H1151) - 65535 - 1)/10, IF(HEX2DEC(H1151) = 32767, IF($X$2=2, S1152, 32767), HEX2DEC(H1151)/10 )) -> 12.8 | T1151: =IF(HEX2DEC(I1151) >= 32768, (HEX2DEC(I1151) - 65535 - 1)/10, IF(HEX2DEC(I1151) = 32767, IF($X$2=2, T1152, 32767), HEX2DEC(I1151)/10 )) -> 18.9 | U1151: =IF(HEX2DEC(J1151) >= 32768, (HEX2DEC(J1151) - 65535 - 1)/10, IF(HEX2DEC(J1151) = 32767, IF($X$2=2, U1152, 32767), IF(OR(AND(H1151="7fff", I1151="7fff", J1151="0",$X$2=2),AND(ABS(T1151)>2, J1151="0",$X$2=2)),U1152,HEX2DEC(J1151)/10 ))) -> 12.2
A1152: 65b907af | B1152: 0 | C1152: 0 | D1152: 0 | E1152: 0 | F1152: 0 | G1152: 0 | H1152: 6b | I1152: 78 | J1152: 58 | L1152: =IF(AND((((HEX2DEC(A1152)/60)/60)/24)+DATE(1970,1,1) >= DATE(YEAR((((HEX2DEC(A1152)/60)/60)/24)+DATE(1970,1,1)),3,24)+WEEKDAY(DATE(YEAR((((HEX2DEC(A1152)/60)/60)/24)+DATE(1970,1,1)),3,31)-1), (((HEX2DEC(A1152)/60)/60)/24)+DATE(1970,1,1) < DATE(YEAR((((HEX2DEC(A1152)/60)/60)/24)+DATE(1970,1,1)),11,1)+26-WEEKDAY(DATE(YEAR((((HEX2DEC(A1152)/60)/60)/24)+DATE(1970,1,1)),11,1)-1)),(((HEX2DEC(A1152)/60)/60)/24)+DATE(1970,1,1)+2/24,(((HEX2DEC(A1152)/60)/60)/24)+DATE(1970,1,1)+1/24) -> 45321.645 | M1152: =IF('tab4'!$B1152=0,0,IF('tab4'!$B1152=1,1,IF('tab4'!$B1152=4,2,IF('tab4'!$B1152=5,3,IF('tab4'!$B1152=6,4,IF(AND('tab4'!$B1152=80,$X$2=2),0,-1)))))) -> 0 | N1152: =IF('tab4'!$C1152=0,0,IF('tab4'!$C1152=1,1,IF('tab4'!$C1152=4,2,IF('tab4'!$C1152=5,3,IF('tab4'!$C1152=6,4,IF(AND('tab4'!$C1152=80,$X$2=2),0,-1)))))) -> 0 | O1152: =D1152 -> 0 | P1152: =E1152 -> 0 | Q1152: =F1152 -> 0 | R1152: =G1152 -> 0 | S1152: =IF(HEX2DEC(H1152) >= 32768, (HEX2DEC(H1152) - 65535 - 1)/10, IF(HEX2DEC(H1152) = 32767, IF($X$2=2, S1153, 32767), HEX2DEC(H1152)/10 )) -> 10.7 | T1152: =IF(HEX2DEC(I1152) >= 32768, (HEX2DEC(I1152) - 65535 - 1)/10, IF(HEX2DEC(I1152) = 32767, IF($X$2=2, T1153, 32767), HEX2DEC(I1152)/10 )) -> 12 | U1152: =IF(HEX2DEC(J1152) >= 32768, (HEX2DEC(J1152) - 65535 - 1)/10, IF(HEX2DEC(J1152) = 32767, IF($X$2=2, U1153, 32767), IF(OR(AND(H1152="7fff", I1152="7fff", J1152="0",$X$2=2),AND(ABS(T1152)>2, J1152="0",$X$2=2)),U1153,HEX2DEC(J1152)/10 ))) -> 8.8
A1153: 65b923d0 | B1153: 0 | C1153: 0 | D1153: 0 | E1153: 0 | F1153: 0 | G1153: 0 | H1153: 48 | I1153: 42 | J1153: 38 | L1153: =IF(AND((((HEX2DEC(A1153)/60)/60)/24)+DATE(1970,1,1) >= DATE(YEAR((((HEX2DEC(A1153)/60)/60)/24)+DATE(1970,1,1)),3,24)+WEEKDAY(DATE(YEAR((((HEX2DEC(A1153)/60)/60)/24)+DATE(1970,1,1)),3,31)-1), (((HEX2DEC(A1153)/60)/60)/24)+DATE(1970,1,1) < DATE(YEAR((((HEX2DEC(A1153)/60)/60)/24)+DATE(1970,1,1)),11,1)+26-WEEKDAY(DATE(YEAR((((HEX2DEC(A1153)/60)/60)/24)+DATE(1970,1,1)),11,1)-1)),(((HEX2DEC(A1153)/60)/60)/24)+DATE(1970,1,1)+2/24,(((HEX2DEC(A1153)/60)/60)/24)+DATE(1970,1,1)+1/24) -> 45321.729 | M1153: =IF('tab4'!$B1153=0,0,IF('tab4'!$B1153=1,1,IF('tab4'!$B1153=4,2,IF('tab4'!$B1153=5,3,IF('tab4'!$B1153=6,4,IF(AND('tab4'!$B1153=80,$X$2=2),0,-1)))))) -> 0 | N1153: =IF('tab4'!$C1153=0,0,IF('tab4'!$C1153=1,1,IF('tab4'!$C1153=4,2,IF('tab4'!$C1153=5,3,IF('tab4'!$C1153=6,4,IF(AND('tab4'!$C1153=80,$X$2=2),0,-1)))))) -> 0 | O1153: =D1153 -> 0 | P1153: =E1153 -> 0 | Q1153: =F1153 -> 0 | R1153: =G1153 -> 0 | S1153: =IF(HEX2DEC(H1153) >= 32768, (HEX2DEC(H1153) - 65535 - 1)/10, IF(HEX2DEC(H1153) = 32767, IF($X$2=2, S1154, 32767), HEX2DEC(H1153)/10 )) -> 7.2 | T1153: =IF(HEX2DEC(I1153) >= 32768, (HEX2DEC(I1153) - 65535 - 1)/10, IF(HEX2DEC(I1153) = 32767, IF($X$2=2, T1154, 32767), HEX2DEC(I1153)/10 )) -> 6.6 | U1153: =IF(HEX2DEC(J1153) >= 32768, (HEX2DEC(J1153) - 65535 - 1)/10, IF(HEX2DEC(J1153) = 32767, IF($X$2=2, U1154, 32767), IF(OR(AND(H1153="7fff", I1153="7fff", J1153="0",$X$2=2),AND(ABS(T1153)>2, J1153="0",$X$2=2)),U1154,HEX2DEC(J1153)/10 ))) -> 5.6
A1154: 65b93ff1 | B1154: 0 | C1154: 0 | D1154: 0 | E1154: 0 | F1154: 0 | G1154: 0 | H1154: 31 | I1154: 25 | J1154: 24 | L1154: =IF(AND((((HEX2DEC(A1154)/60)/60)/24)+DATE(1970,1,1) >= DATE(YEAR((((HEX2DEC(A1154)/60)/60)/24)+DATE(1970,1,1)),3,24)+WEEKDAY(DATE(YEAR((((HEX2DEC(A1154)/60)/60)/24)+DATE(1970,1,1)),3,31)-1), (((HEX2DEC(A1154)/60)/60)/24)+DATE(1970,1,1) < DATE(YEAR((((HEX2DEC(A1154)/60)/60)/24)+DATE(1970,1,1)),11,1)+26-WEEKDAY(DATE(YEAR((((HEX2DEC(A1154)/60)/60)/24)+DATE(1970,1,1)),11,1)-1)),(((HEX2DEC(A1154)/60)/60)/24)+DATE(1970,1,1)+2/24,(((HEX2DEC(A1154)/60)/60)/24)+DATE(1970,1,1)+1/24) -> 45321.812 | M1154: =IF('tab4'!$B1154=0,0,IF('tab4'!$B1154=1,1,IF('tab4'!$B1154=4,2,IF('tab4'!$B1154=5,3,IF('tab4'!$B1154=6,4,IF(AND('tab4'!$B1154=80,$X$2=2),0,-1)))))) -> 0 | N1154: =IF('tab4'!$C1154=0,0,IF('tab4'!$C1154=1,1,IF('tab4'!$C1154=4,2,IF('tab4'!$C1154=5,3,IF('tab4'!$C1154=6,4,IF(AND('tab4'!$C1154=80,$X$2=2),0,-1)))))) -> 0 | O1154: =D1154 -> 0 | P1154: =E1154 -> 0 | Q1154: =F1154 -> 0 | R1154: =G1154 -> 0 | S1154: =IF(HEX2DEC(H1154) >= 32768, (HEX2DEC(H1154) - 65535 - 1)/10, IF(HEX2DEC(H1154) = 32767, IF($X$2=2, S1155, 32767), HEX2DEC(H1154)/10 )) -> 4.9 | T1154: =IF(HEX2DEC(I1154) >= 32768, (HEX2DEC(I1154) - 65535 - 1)/10, IF(HEX2DEC(I1154) = 32767, IF($X$2=2, T1155, 32767), HEX2DEC(I1154)/10 )) -> 3.7 | U1154: =IF(HEX2DEC(J1154) >= 32768, (HEX2DEC(J1154) - 65535 - 1)/10, IF(HEX2DEC(J1154) = 32767, IF($X$2=2, U1155, 32767), IF(OR(AND(H1154="7fff", I1154="7fff", J1154="0",$X$2=2),AND(ABS(T1154)>2, J1154="0",$X$2=2)),U1155,HEX2DEC(J1154)/10 ))) -> 3.6
A1155: 65b95c11 | B1155: 0 | C1155: 0 | D1155: 0 | E1155: 0 | F1155: 0 | G1155: 0 | H1155: 26 | I1155: 1e | J1155: 29 | L1155: =IF(AND((((HEX2DEC(A1155)/60)/60)/24)+DATE(1970,1,1) >= DATE(YEAR((((HEX2DEC(A1155)/60)/60)/24)+DATE(1970,1,1)),3,24)+WEEKDAY(DATE(YEAR((((HEX2DEC(A1155)/60)/60)/24)+DATE(1970,1,1)),3,31)-1), (((HEX2DEC(A1155)/60)/60)/24)+DATE(1970,1,1) < DATE(YEAR((((HEX2DEC(A1155)/60)/60)/24)+DATE(1970,1,1)),11,1)+26-WEEKDAY(DATE(YEAR((((HEX2DEC(A1155)/60)/60)/24)+DATE(1970,1,1)),11,1)-1)),(((HEX2DEC(A1155)/60)/60)/24)+DATE(1970,1,1)+2/24,(((HEX2DEC(A1155)/60)/60)/24)+DATE(1970,1,1)+1/24) -> 45321.895 | M1155: =IF('tab4'!$B1155=0,0,IF('tab4'!$B1155=1,1,IF('tab4'!$B1155=4,2,IF('tab4'!$B1155=5,3,IF('tab4'!$B1155=6,4,IF(AND('tab4'!$B1155=80,$X$2=2),0,-1)))))) -> 0 | N1155: =IF('tab4'!$C1155=0,0,IF('tab4'!$C1155=1,1,IF('tab4'!$C1155=4,2,IF('tab4'!$C1155=5,3,IF('tab4'!$C1155=6,4,IF(AND('tab4'!$C1155=80,$X$2=2),0,-1)))))) -> 0 | O1155: =D1155 -> 0 | P1155: =E1155 -> 0 | Q1155: =F1155 -> 0 | R1155: =G1155 -> 0 | S1155: =IF(HEX2DEC(H1155) >= 32768, (HEX2DEC(H1155) - 65535 - 1)/10, IF(HEX2DEC(H1155) = 32767, IF($X$2=2, S1156, 32767), HEX2DEC(H1155)/10 )) -> 3.8 | T1155: =IF(HEX2DEC(I1155) >= 32768, (HEX2DEC(I1155) - 65535 - 1)/10, IF(HEX2DEC(I1155) = 32767, IF($X$2=2, T1156, 32767), HEX2DEC(I1155)/10 )) -> 3 | U1155: =IF(HEX2DEC(J1155) >= 32768, (HEX2DEC(J1155) - 65535 - 1)/10, IF(HEX2DEC(J1155) = 32767, IF($X$2=2, U1156, 32767), IF(OR(AND(H1155="7fff", I1155="7fff", J1155="0",$X$2=2),AND(ABS(T1155)>2, J1155="0",$X$2=2)),U1156,HEX2DEC(J1155)/10 ))) -> 4.1
A1156: 65b97832 | B1156: 0 | C1156: 0 | D1156: 0 | E1156: 0 | F1156: 0 | G1156: 0 | H1156: 25 | I1156: 20 | J1156: 2a | L1156: =IF(AND((((HEX2DEC(A1156)/60)/60)/24)+DATE(1970,1,1) >= DATE(YEAR((((HEX2DEC(A1156)/60)/60)/24)+DATE(1970,1,1)),3,24)+WEEKDAY(DATE(YEAR((((HEX2DEC(A1156)/60)/60)/24)+DATE(1970,1,1)),3,31)-1), (((HEX2DEC(A1156)/60)/60)/24)+DATE(1970,1,1) < DATE(YEAR((((HEX2DEC(A1156)/60)/60)/24)+DATE(1970,1,1)),11,1)+26-WEEKDAY(DATE(YEAR((((HEX2DEC(A1156)/60)/60)/24)+DATE(1970,1,1)),11,1)-1)),(((HEX2DEC(A1156)/60)/60)/24)+DATE(1970,1,1)+2/24,(((HEX2DEC(A1156)/60)/60)/24)+DATE(1970,1,1)+1/24) -> 45321.979 | M1156: =IF('tab4'!$B1156=0,0,IF('tab4'!$B1156=1,1,IF('tab4'!$B1156=4,2,IF('tab4'!$B1156=5,3,IF('tab4'!$B1156=6,4,IF(AND('tab4'!$B1156=80,$X$2=2),0,-1)))))) -> 0 | N1156: =IF('tab4'!$C1156=0,0,IF('tab4'!$C1156=1,1,IF('tab4'!$C1156=4,2,IF('tab4'!$C1156=5,3,IF('tab4'!$C1156=6,4,IF(AND('tab4'!$C1156=80,$X$2=2),0,-1)))))) -> 0 | O1156: =D1156 -> 0 | P1156: =E1156 -> 0 | Q1156: =F1156 -> 0 | R1156: =G1156 -> 0 | S1156: =IF(HEX2DEC(H1156) >= 32768, (HEX2DEC(H1156) - 65535 - 1)/10, IF(HEX2DEC(H1156) = 32767, IF($X$2=2, S1157, 32767), HEX2DEC(H1156)/10 )) -> 3.7 | T1156: =IF(HEX2DEC(I1156) >= 32768, (HEX2DEC(I1156) - 65535 - 1)/10, IF(HEX2DEC(I1156) = 32767, IF($X$2=2, T1157, 32767), HEX2DEC(I1156)/10 )) -> 3.2 | U1156: =IF(HEX2DEC(J1156) >= 32768, (HEX2DEC(J1156) - 65535 - 1)/10, IF(HEX2DEC(J1156) = 32767, IF($X$2=2, U1157, 32767), IF(OR(AND(H1156="7fff", I1156="7fff", J1156="0",$X$2=2),AND(ABS(T1156)>2, J1156="0",$X$2=2)),U1157,HEX2DEC(J1156)/10 ))) -> 4.2
A1157: 65b99453 | B1157: 0 | C1157: 0 | D1157: 0 | E1157: 0 | F1157: 0 | G1157: 0 | H1157: 27 | I1157: 21 | J1157: 2b | L1157: =IF(AND((((HEX2DEC(A1157)/60)/60)/24)+DATE(1970,1,1) >= DATE(YEAR((((HEX2DEC(A1157)/60)/60)/24)+DATE(1970,1,1)),3,24)+WEEKDAY(DATE(YEAR((((HEX2DEC(A1157)/60)/60)/24)+DATE(1970,1,1)),3,31)-1), (((HEX2DEC(A1157)/60)/60)/24)+DATE(1970,1,1) < DATE(YEAR((((HEX2DEC(A1157)/60)/60)/24)+DATE(1970,1,1)),11,1)+26-WEEKDAY(DATE(YEAR((((HEX2DEC(A1157)/60)/60)/24)+DATE(1970,1,1)),11,1)-1)),(((HEX2DEC(A1157)/60)/60)/24)+DATE(1970,1,1)+2/24,(((HEX2DEC(A1157)/60)/60)/24)+DATE(1970,1,1)+1/24) -> 45322.062 | M1157: =IF('tab4'!$B1157=0,0,IF('tab4'!$B1157=1,1,IF('tab4'!$B1157=4,2,IF('tab4'!$B1157=5,3,IF('tab4'!$B1157=6,4,IF(AND('tab4'!$B1157=80,$X$2=2),0,-1)))))) -> 0 | N1157: =IF('tab4'!$C1157=0,0,IF('tab4'!$C1157=1,1,IF('tab4'!$C1157=4,2,IF('tab4'!$C1157=5,3,IF('tab4'!$C1157=6,4,IF(AND('tab4'!$C1157=80,$X$2=2),0,-1)))))) -> 0 | O1157: =D1157 -> 0 | P1157: =E1157 -> 0 | Q1157: =F1157 -> 0 | R1157: =G1157 -> 0 | S1157: =IF(HEX2DEC(H1157) >= 32768, (HEX2DEC(H1157) - 65535 - 1)/10, IF(HEX2DEC(H1157) = 32767, IF($X$2=2, S1158, 32767), HEX2DEC(H1157)/10 )) -> 3.9 | T1157: =IF(HEX2DEC(I1157) >= 32768, (HEX2DEC(I1157) - 65535 - 1)/10, IF(HEX2DEC(I1157) = 32767, IF($X$2=2, T1158, 32767), HEX2DEC(I1157)/10 )) -> 3.3 | U1157: =IF(HEX2DEC(J1157) >= 32768, (HEX2DEC(J1157) - 65535 - 1)/10, IF(HEX2DEC(J1157) = 32767, IF($X$2=2, U1158, 32767), IF(OR(AND(H1157="7fff", I1157="7fff", J1157="0",$X$2=2),AND(ABS(T1157)>2, J1157="0",$X$2=2)),U1158,HEX2DEC(J1157)/10 ))) -> 4.3
A1158: 65b9b073 | B1158: 0 | C1158: 0 | D1158: 0 | E1158: 0 | F1158: 0 | G1158: 0 | H1158: 2e | I1158: 2d | J1158: 33 | L1158: =IF(AND((((HEX2DEC(A1158)/60)/60)/24)+DATE(1970,1,1) >= DATE(YEAR((((HEX2DEC(A1158)/60)/60)/24)+DATE(1970,1,1)),3,24)+WEEKDAY(DATE(YEAR((((HEX2DEC(A1158)/60)/60)/24)+DATE(1970,1,1)),3,31)-1), (((HEX2DEC(A1158)/60)/60)/24)+DATE(1970,1,1) < DATE(YEAR((((HEX2DEC(A1158)/60)/60)/24)+DATE(1970,1,1)),11,1)+26-WEEKDAY(DATE(YEAR((((HEX2DEC(A1158)/60)/60)/24)+DATE(1970,1,1)),11,1)-1)),(((HEX2DEC(A1158)/60)/60)/24)+DATE(1970,1,1)+2/24,(((HEX2DEC(A1158)/60)/60)/24)+DATE(1970,1,1)+1/24) -> 45322.145 | M1158: =IF('tab4'!$B1158=0,0,IF('tab4'!$B1158=1,1,IF('tab4'!$B1158=4,2,IF('tab4'!$B1158=5,3,IF('tab4'!$B1158=6,4,IF(AND('tab4'!$B1158=80,$X$2=2),0,-1)))))) -> 0 | N1158: =IF('tab4'!$C1158=0,0,IF('tab4'!$C1158=1,1,IF('tab4'!$C1158=4,2,IF('tab4'!$C1158=5,3,IF('tab4'!$C1158=6,4,IF(AND('tab4'!$C1158=80,$X$2=2),0,-1)))))) -> 0 | O1158: =D1158 -> 0 | P1158: =E1158 -> 0 | Q1158: =F1158 -> 0 | R1158: =G1158 -> 0 | S1158: =IF(HEX2DEC(H1158) >= 32768, (HEX2DEC(H1158) - 65535 - 1)/10, IF(HEX2DEC(H1158) = 32767, IF($X$2=2, S1159, 32767), HEX2DEC(H1158)/10 )) -> 4.6 | T1158: =IF(HEX2DEC(I1158) >= 32768, (HEX2DEC(I1158) - 65535 - 1)/10, IF(HEX2DEC(I1158) = 32767, IF($X$2=2, T1159, 32767), HEX2DEC(I1158)/10 )) -> 4.5 | U1158: =IF(HEX2DEC(J1158) >= 32768, (HEX2DEC(J1158) - 65535 - 1)/10, IF(HEX2DEC(J1158) = 32767, IF($X$2=2, U1159, 32767), IF(OR(AND(H1158="7fff", I1158="7fff", J1158="0",$X$2=2),AND(ABS(T1158)>2, J1158="0",$X$2=2)),U1159,HEX2DEC(J1158)/10 ))) -> 5.1
A1159: 65b9cc94 | B1159: 0 | C1159: 0 | D1159: 0 | E1159: 0 | F1159: 0 | G1159: 0 | H1159: 32 | I1159: 30 | J1159: 35 | L1159: =IF(AND((((HEX2DEC(A1159)/60)/60)/24)+DATE(1970,1,1) >= DATE(YEAR((((HEX2DEC(A1159)/60)/60)/24)+DATE(1970,1,1)),3,24)+WEEKDAY(DATE(YEAR((((HEX2DEC(A1159)/60)/60)/24)+DATE(1970,1,1)),3,31)-1), (((HEX2DEC(A1159)/60)/60)/24)+DATE(1970,1,1) < DATE(YEAR((((HEX2DEC(A1159)/60)/60)/24)+DATE(1970,1,1)),11,1)+26-WEEKDAY(DATE(YEAR((((HEX2DEC(A1159)/60)/60)/24)+DATE(1970,1,1)),11,1)-1)),(((HEX2DEC(A1159)/60)/60)/24)+DATE(1970,1,1)+2/24,(((HEX2DEC(A1159)/60)/60)/24)+DATE(1970,1,1)+1/24) -> 45322.229 | M1159: =IF('tab4'!$B1159=0,0,IF('tab4'!$B1159=1,1,IF('tab4'!$B1159=4,2,IF('tab4'!$B1159=5,3,IF('tab4'!$B1159=6,4,IF(AND('tab4'!$B1159=80,$X$2=2),0,-1)))))) -> 0 | N1159: =IF('tab4'!$C1159=0,0,IF('tab4'!$C1159=1,1,IF('tab4'!$C1159=4,2,IF('tab4'!$C1159=5,3,IF('tab4'!$C1159=6,4,IF(AND('tab4'!$C1159=80,$X$2=2),0,-1)))))) -> 0 | O1159: =D1159 -> 0 | P1159: =E1159 -> 0 | Q1159: =F1159 -> 0 | R1159: =G1159 -> 0 | S1159: =IF(HEX2DEC(H1159) >= 32768, (HEX2DEC(H1159) - 65535 - 1)/10, IF(HEX2DEC(H1159) = 32767, IF($X$2=2, S1160, 32767), HEX2DEC(H1159)/10 )) -> 5 | T1159: =IF(HEX2DEC(I1159) >= 32768, (HEX2DEC(I1159) - 65535 - 1)/10, IF(HEX2DEC(I1159) = 32767, IF($X$2=2, T1160, 32767), HEX2DEC(I1159)/10 )) -> 4.8 | U1159: =IF(HEX2DEC(J1159) >= 32768, (HEX2DEC(J1159) - 65535 - 1)/10, IF(HEX2DEC(J1159) = 32767, IF($X$2=2, U1160, 32767), IF(OR(AND(H1159="7fff", I1159="7fff", J1159="0",$X$2=2),AND(ABS(T1159)>2, J1159="0",$X$2=2)),U1160,HEX2DEC(J1159)/10 ))) -> 5.3
A1160: 65b9e8b5 | B1160: 0 | C1160: 0 | D1160: 0 | E1160: 0 | F1160: 0 | G1160: 0 | H1160: 35 | I1160: 33 | J1160: 36 | L1160: =IF(AND((((HEX2DEC(A1160)/60)/60)/24)+DATE(1970,1,1) >= DATE(YEAR((((HEX2DEC(A1160)/60)/60)/24)+DATE(1970,1,1)),3,24)+WEEKDAY(DATE(YEAR((((HEX2DEC(A1160)/60)/60)/24)+DATE(1970,1,1)),3,31)-1), (((HEX2DEC(A1160)/60)/60)/24)+DATE(1970,1,1) < DATE(YEAR((((HEX2DEC(A1160)/60)/60)/24)+DATE(1970,1,1)),11,1)+26-WEEKDAY(DATE(YEAR((((HEX2DEC(A1160)/60)/60)/24)+DATE(1970,1,1)),11,1)-1)),(((HEX2DEC(A1160)/60)/60)/24)+DATE(1970,1,1)+2/24,(((HEX2DEC(A1160)/60)/60)/24)+DATE(1970,1,1)+1/24) -> 45322.312 | M1160: =IF('tab4'!$B1160=0,0,IF('tab4'!$B1160=1,1,IF('tab4'!$B1160=4,2,IF('tab4'!$B1160=5,3,IF('tab4'!$B1160=6,4,IF(AND('tab4'!$B1160=80,$X$2=2),0,-1)))))) -> 0 | N1160: =IF('tab4'!$C1160=0,0,IF('tab4'!$C1160=1,1,IF('tab4'!$C1160=4,2,IF('tab4'!$C1160=5,3,IF('tab4'!$C1160=6,4,IF(AND('tab4'!$C1160=80,$X$2=2),0,-1)))))) -> 0 | O1160: =D1160 -> 0 | P1160: =E1160 -> 0 | Q1160: =F1160 -> 0 | R1160: =G1160 -> 0 | S1160: =IF(HEX2DEC(H1160) >= 32768, (HEX2DEC(H1160) - 65535 - 1)/10, IF(HEX2DEC(H1160) = 32767, IF($X$2=2, S1161, 32767), HEX2DEC(H1160)/10 )) -> 5.3 | T1160: =IF(HEX2DEC(I1160) >= 32768, (HEX2DEC(I1160) - 65535 - 1)/10, IF(HEX2DEC(I1160) = 32767, IF($X$2=2, T1161, 32767), HEX2DEC(I1160)/10 )) -> 5.1 | U1160: =IF(HEX2DEC(J1160) >= 32768, (HEX2DEC(J1160) - 65535 - 1)/10, IF(HEX2DEC(J1160) = 32767, IF($X$2=2, U1161, 32767), IF(OR(AND(H1160="7fff", I1160="7fff", J1160="0",$X$2=2),AND(ABS(T1160)>2, J1160="0",$X$2=2)),U1161,HEX2DEC(J1160)/10 ))) -> 5.4
A1161: 65ba04d6 | B1161: 0 | C1161: 0 | D1161: 0 | E1161: 0 | F1161: 0 | G1161: 0 | H1161: 3d | I1161: 3e | J1161: 41 | L1161: =IF(AND((((HEX2DEC(A1161)/60)/60)/24)+DATE(1970,1,1) >= DATE(YEAR((((HEX2DEC(A1161)/60)/60)/24)+DATE(1970,1,1)),3,24)+WEEKDAY(DATE(YEAR((((HEX2DEC(A1161)/60)/60)/24)+DATE(1970,1,1)),3,31)-1), (((HEX2DEC(A1161)/60)/60)/24)+DATE(1970,1,1) < DATE(YEAR((((HEX2DEC(A1161)/60)/60)/24)+DATE(1970,1,1)),11,1)+26-WEEKDAY(DATE(YEAR((((HEX2DEC(A1161)/60)/60)/24)+DATE(1970,1,1)),11,1)-1)),(((HEX2DEC(A1161)/60)/60)/24)+DATE(1970,1,1)+2/24,(((HEX2DEC(A1161)/60)/60)/24)+DATE(1970,1,1)+1/24) -> 45322.395 | M1161: =IF('tab4'!$B1161=0,0,IF('tab4'!$B1161=1,1,IF('tab4'!$B1161=4,2,IF('tab4'!$B1161=5,3,IF('tab4'!$B1161=6,4,IF(AND('tab4'!$B1161=80,$X$2=2),0,-1)))))) -> 0 | N1161: =IF('tab4'!$C1161=0,0,IF('tab4'!$C1161=1,1,IF('tab4'!$C1161=4,2,IF('tab4'!$C1161=5,3,IF('tab4'!$C1161=6,4,IF(AND('tab4'!$C1161=80,$X$2=2),0,-1)))))) -> 0 | O1161: =D1161 -> 0 | P1161: =E1161 -> 0 | Q1161: =F1161 -> 0 | R1161: =G1161 -> 0 | S1161: =IF(HEX2DEC(H1161) >= 32768, (HEX2DEC(H1161) - 65535 - 1)/10, IF(HEX2DEC(H1161) = 32767, IF($X$2=2, S1162, 32767), HEX2DEC(H1161)/10 )) -> 6.1 | T1161: =IF(HEX2DEC(I1161) >= 32768, (HEX2DEC(I1161) - 65535 - 1)/10, IF(HEX2DEC(I1161) = 32767, IF($X$2=2, T1162, 32767), HEX2DEC(I1161)/10 )) -> 6.2 | U1161: =IF(HEX2DEC(J1161) >= 32768, (HEX2DEC(J1161) - 65535 - 1)/10, IF(HEX2DEC(J1161) = 32767, IF($X$2=2, U1162, 32767), IF(OR(AND(H1161="7fff", I1161="7fff", J1161="0",$X$2=2),AND(ABS(T1161)>2, J1161="0",$X$2=2)),U1162,HEX2DEC(J1161)/10 ))) -> 6.5
A1162: 65ba20f6 | B1162: 0 | C1162: 0 | D1162: 0 | E1162: 0 | F1162: 0 | G1162: 0 | H1162: 59 | I1162: 64 | J1162: 4f | L1162: =IF(AND((((HEX2DEC(A1162)/60)/60)/24)+DATE(1970,1,1) >= DATE(YEAR((((HEX2DEC(A1162)/60)/60)/24)+DATE(1970,1,1)),3,24)+WEEKDAY(DATE(YEAR((((HEX2DEC(A1162)/60)/60)/24)+DATE(1970,1,1)),3,31)-1), (((HEX2DEC(A1162)/60)/60)/24)+DATE(1970,1,1) < DATE(YEAR((((HEX2DEC(A1162)/60)/60)/24)+DATE(1970,1,1)),11,1)+26-WEEKDAY(DATE(YEAR((((HEX2DEC(A1162)/60)/60)/24)+DATE(1970,1,1)),11,1)-1)),(((HEX2DEC(A1162)/60)/60)/24)+DATE(1970,1,1)+2/24,(((HEX2DEC(A1162)/60)/60)/24)+DATE(1970,1,1)+1/24) -> 45322.479 | M1162: =IF('tab4'!$B1162=0,0,IF('tab4'!$B1162=1,1,IF('tab4'!$B1162=4,2,IF('tab4'!$B1162=5,3,IF('tab4'!$B1162=6,4,IF(AND('tab4'!$B1162=80,$X$2=2),0,-1)))))) -> 0 | N1162: =IF('tab4'!$C1162=0,0,IF('tab4'!$C1162=1,1,IF('tab4'!$C1162=4,2,IF('tab4'!$C1162=5,3,IF('tab4'!$C1162=6,4,IF(AND('tab4'!$C1162=80,$X$2=2),0,-1)))))) -> 0 | O1162: =D1162 -> 0 | P1162: =E1162 -> 0 | Q1162: =F1162 -> 0 | R1162: =G1162 -> 0 | S1162: =IF(HEX2DEC(H1162) >= 32768, (HEX2DEC(H1162) - 65535 - 1)/10, IF(HEX2DEC(H1162) = 32767, IF($X$2=2, S1163, 32767), HEX2DEC(H1162)/10 )) -> 8.9 | T1162: =IF(HEX2DEC(I1162) >= 32768, (HEX2DEC(I1162) - 65535 - 1)/10, IF(HEX2DEC(I1162) = 32767, IF($X$2=2, T1163, 32767), HEX2DEC(I1162)/10 )) -> 10 | U1162: =IF(HEX2DEC(J1162) >= 32768, (HEX2DEC(J1162) - 65535 - 1)/10, IF(HEX2DEC(J1162) = 32767, IF($X$2=2, U1163, 32767), IF(OR(AND(H1162="7fff", I1162="7fff", J1162="0",$X$2=2),AND(ABS(T1162)>2, J1162="0",$X$2=2)),U1163,HEX2DEC(J1162)/10 ))) -> 7.9
A1163: 65ba3d17 | B1163: 0 | C1163: 0 | D1163: 0 | E1163: 0 | F1163: 0 | G1163: 0 | H1163: 63 | I1163: 69 | J1163: 55 | L1163: =IF(AND((((HEX2DEC(A1163)/60)/60)/24)+DATE(1970,1,1) >= DATE(YEAR((((HEX2DEC(A1163)/60)/60)/24)+DATE(1970,1,1)),3,24)+WEEKDAY(DATE(YEAR((((HEX2DEC(A1163)/60)/60)/24)+DATE(1970,1,1)),3,31)-1), (((HEX2DEC(A1163)/60)/60)/24)+DATE(1970,1,1) < DATE(YEAR((((HEX2DEC(A1163)/60)/60)/24)+DATE(1970,1,1)),11,1)+26-WEEKDAY(DATE(YEAR((((HEX2DEC(A1163)/60)/60)/24)+DATE(1970,1,1)),11,1)-1)),(((HEX2DEC(A1163)/60)/60)/24)+DATE(1970,1,1)+2/24,(((HEX2DEC(A1163)/60)/60)/24)+DATE(1970,1,1)+1/24) -> 45322.562 | M1163: =IF('tab4'!$B1163=0,0,IF('tab4'!$B1163=1,1,IF('tab4'!$B1163=4,2,IF('tab4'!$B1163=5,3,IF('tab4'!$B1163=6,4,IF(AND('tab4'!$B1163=80,$X$2=2),0,-1)))))) -> 0 | N1163: =IF('tab4'!$C1163=0,0,IF('tab4'!$C1163=1,1,IF('tab4'!$C1163=4,2,IF('tab4'!$C1163=5,3,IF('tab4'!$C1163=6,4,IF(AND('tab4'!$C1163=80,$X$2=2),0,-1)))))) -> 0 | O1163: =D1163 -> 0 | P1163: =E1163 -> 0 | Q1163: =F1163 -> 0 | R1163: =G1163 -> 0 | S1163: =IF(HEX2DEC(H1163) >= 32768, (HEX2DEC(H1163) - 65535 - 1)/10, IF(HEX2DEC(H1163) = 32767, IF($X$2=2, S1164, 32767), HEX2DEC(H1163)/10 )) -> 9.9 | T1163: =IF(HEX2DEC(I1163) >= 32768, (HEX2DEC(I1163) - 65535 - 1)/10, IF(HEX2DEC(I1163) = 32767, IF($X$2=2, T1164, 32767), HEX2DEC(I1163)/10 )) -> 10.5 | U1163: =IF(HEX2DEC(J1163) >= 32768, (HEX2DEC(J1163) - 65535 - 1)/10, IF(HEX2DEC(J1163) = 32767, IF($X$2=2, U1164, 32767), IF(OR(AND(H1163="7fff", I1163="7fff", J1163="0",$X$2=2),AND(ABS(T1163)>2, J1163="0",$X$2=2)),U1164,HEX2DEC(J1163)/10 ))) -> 8.5
A1164: 65ba5937 | B1164: 0 | C1164: 0 | D1164: 0 | E1164: 0 | F1164: 0 | G1164: 0 | H1164: 5d | I1164: 5c | J1164: 4d | L1164: =IF(AND((((HEX2DEC(A1164)/60)/60)/24)+DATE(1970,1,1) >= DATE(YEAR((((HEX2DEC(A1164)/60)/60)/24)+DATE(1970,1,1)),3,24)+WEEKDAY(DATE(YEAR((((HEX2DEC(A1164)/60)/60)/24)+DATE(1970,1,1)),3,31)-1), (((HEX2DEC(A1164)/60)/60)/24)+DATE(1970,1,1) < DATE(YEAR((((HEX2DEC(A1164)/60)/60)/24)+DATE(1970,1,1)),11,1)+26-WEEKDAY(DATE(YEAR((((HEX2DEC(A1164)/60)/60)/24)+DATE(1970,1,1)),11,1)-1)),(((HEX2DEC(A1164)/60)/60)/24)+DATE(1970,1,1)+2/24,(((HEX2DEC(A1164)/60)/60)/24)+DATE(1970,1,1)+1/24) -> 45322.645 | M1164: =IF('tab4'!$B1164=0,0,IF('tab4'!$B1164=1,1,IF('tab4'!$B1164=4,2,IF('tab4'!$B1164=5,3,IF('tab4'!$B1164=6,4,IF(AND('tab4'!$B1164=80,$X$2=2),0,-1)))))) -> 0 | N1164: =IF('tab4'!$C1164=0,0,IF('tab4'!$C1164=1,1,IF('tab4'!$C1164=4,2,IF('tab4'!$C1164=5,3,IF('tab4'!$C1164=6,4,IF(AND('tab4'!$C1164=80,$X$2=2),0,-1)))))) -> 0 | O1164: =D1164 -> 0 | P1164: =E1164 -> 0 | Q1164: =F1164 -> 0 | R1164: =G1164 -> 0 | S1164: =IF(HEX2DEC(H1164) >= 32768, (HEX2DEC(H1164) - 65535 - 1)/10, IF(HEX2DEC(H1164) = 32767, IF($X$2=2, S1165, 32767), HEX2DEC(H1164)/10 )) -> 9.3 | T1164: =IF(HEX2DEC(I1164) >= 32768, (HEX2DEC(I1164) - 65535 - 1)/10, IF(HEX2DEC(I1164) = 32767, IF($X$2=2, T1165, 32767), HEX2DEC(I1164)/10 )) -> 9.2 | U1164: =IF(HEX2DEC(J1164) >= 32768, (HEX2DEC(J1164) - 65535 - 1)/10, IF(HEX2DEC(J1164) = 32767, IF($X$2=2, U1165, 32767), IF(OR(AND(H1164="7fff", I1164="7fff", J1164="0",$X$2=2),AND(ABS(T1164)>2, J1164="0",$X$2=2)),U1165,HEX2DEC(J1164)/10 ))) -> 7.7
A1165: 65ba7558 | B1165: 0 | C1165: 0 | D1165: 0 | E1165: 0 | F1165: 0 | G1165: 0 | H1165: 4b | I1165: 47 | J1165: 40 | L1165: =IF(AND((((HEX2DEC(A1165)/60)/60)/24)+DATE(1970,1,1) >= DATE(YEAR((((HEX2DEC(A1165)/60)/60)/24)+DATE(1970,1,1)),3,24)+WEEKDAY(DATE(YEAR((((HEX2DEC(A1165)/60)/60)/24)+DATE(1970,1,1)),3,31)-1), (((HEX2DEC(A1165)/60)/60)/24)+DATE(1970,1,1) < DATE(YEAR((((HEX2DEC(A1165)/60)/60)/24)+DATE(1970,1,1)),11,1)+26-WEEKDAY(DATE(YEAR((((HEX2DEC(A1165)/60)/60)/24)+DATE(1970,1,1)),11,1)-1)),(((HEX2DEC(A1165)/60)/60)/24)+DATE(1970,1,1)+2/24,(((HEX2DEC(A1165)/60)/60)/24)+DATE(1970,1,1)+1/24) -> 45322.729 | M1165: =IF('tab4'!$B1165=0,0,IF('tab4'!$B1165=1,1,IF('tab4'!$B1165=4,2,IF('tab4'!$B1165=5,3,IF('tab4'!$B1165=6,4,IF(AND('tab4'!$B1165=80,$X$2=2),0,-1)))))) -> 0 | N1165: =IF('tab4'!$C1165=0,0,IF('tab4'!$C1165=1,1,IF('tab4'!$C1165=4,2,IF('tab4'!$C1165=5,3,IF('tab4'!$C1165=6,4,IF(AND('tab4'!$C1165=80,$X$2=2),0,-1)))))) -> 0 | O1165: =D1165 -> 0 | P1165: =E1165 -> 0 | Q1165: =F1165 -> 0 | R1165: =G1165 -> 0 | S1165: =IF(HEX2DEC(H1165) >= 32768, (HEX2DEC(H1165) - 65535 - 1)/10, IF(HEX2DEC(H1165) = 32767, IF($X$2=2, S1166, 32767), HEX2DEC(H1165)/10 )) -> 7.5 | T1165: =IF(HEX2DEC(I1165) >= 32768, (HEX2DEC(I1165) - 65535 - 1)/10, IF(HEX2DEC(I1165) = 32767, IF($X$2=2, T1166, 32767), HEX2DEC(I1165)/10 )) -> 7.1 | U1165: =IF(HEX2DEC(J1165) >= 32768, (HEX2DEC(J1165) - 65535 - 1)/10, IF(HEX2DEC(J1165) = 32767, IF($X$2=2, U1166, 32767), IF(OR(AND(H1165="7fff", I1165="7fff", J1165="0",$X$2=2),AND(ABS(T1165)>2, J1165="0",$X$2=2)),U1166,HEX2DEC(J1165)/10 ))) -> 6.4
A1166: 65ba9178 | B1166: 0 | C1166: 0 | D1166: 0 | E1166: 0 | F1166: 0 | G1166: 0 | H1166: 41 | I1166: 3d | J1166: 3a | L1166: =IF(AND((((HEX2DEC(A1166)/60)/60)/24)+DATE(1970,1,1) >= DATE(YEAR((((HEX2DEC(A1166)/60)/60)/24)+DATE(1970,1,1)),3,24)+WEEKDAY(DATE(YEAR((((HEX2DEC(A1166)/60)/60)/24)+DATE(1970,1,1)),3,31)-1), (((HEX2DEC(A1166)/60)/60)/24)+DATE(1970,1,1) < DATE(YEAR((((HEX2DEC(A1166)/60)/60)/24)+DATE(1970,1,1)),11,1)+26-WEEKDAY(DATE(YEAR((((HEX2DEC(A1166)/60)/60)/24)+DATE(1970,1,1)),11,1)-1)),(((HEX2DEC(A1166)/60)/60)/24)+DATE(1970,1,1)+2/24,(((HEX2DEC(A1166)/60)/60)/24)+DATE(1970,1,1)+1/24) -> 45322.812 | M1166: =IF('tab4'!$B1166=0,0,IF('tab4'!$B1166=1,1,IF('tab4'!$B1166=4,2,IF('tab4'!$B1166=5,3,IF('tab4'!$B1166=6,4,IF(AND('tab4'!$B1166=80,$X$2=2),0,-1)))))) -> 0 | N1166: =IF('tab4'!$C1166=0,0,IF('tab4'!$C1166=1,1,IF('tab4'!$C1166=4,2,IF('tab4'!$C1166=5,3,IF('tab4'!$C1166=6,4,IF(AND('tab4'!$C1166=80,$X$2=2),0,-1)))))) -> 0 | O1166: =D1166 -> 0 | P1166: =E1166 -> 0 | Q1166: =F1166 -> 0 | R1166: =G1166 -> 0 | S1166: =IF(HEX2DEC(H1166) >= 32768, (HEX2DEC(H1166) - 65535 - 1)/10, IF(HEX2DEC(H1166) = 32767, IF($X$2=2, S1167, 32767), HEX2DEC(H1166)/10 )) -> 6.5 | T1166: =IF(HEX2DEC(I1166) >= 32768, (HEX2DEC(I1166) - 65535 - 1)/10, IF(HEX2DEC(I1166) = 32767, IF($X$2=2, T1167, 32767), HEX2DEC(I1166)/10 )) -> 6.1 | U1166: =IF(HEX2DEC(J1166) >= 32768, (HEX2DEC(J1166) - 65535 - 1)/10, IF(HEX2DEC(J1166) = 32767, IF($X$2=2, U1167, 32767), IF(OR(AND(H1166="7fff", I1166="7fff", J1166="0",$X$2=2),AND(ABS(T1166)>2, J1166="0",$X$2=2)),U1167,HEX2DEC(J1166)/10 ))) -> 5.8
A1167: 65baad99 | B1167: 0 | C1167: 0 | D1167: 0 | E1167: 0 | F1167: 0 | G1167: 0 | H1167: 2c | I1167: 24 | J1167: 1a | L1167: =IF(AND((((HEX2DEC(A1167)/60)/60)/24)+DATE(1970,1,1) >= DATE(YEAR((((HEX2DEC(A1167)/60)/60)/24)+DATE(1970,1,1)),3,24)+WEEKDAY(DATE(YEAR((((HEX2DEC(A1167)/60)/60)/24)+DATE(1970,1,1)),3,31)-1), (((HEX2DEC(A1167)/60)/60)/24)+DATE(1970,1,1) < DATE(YEAR((((HEX2DEC(A1167)/60)/60)/24)+DATE(1970,1,1)),11,1)+26-WEEKDAY(DATE(YEAR((((HEX2DEC(A1167)/60)/60)/24)+DATE(1970,1,1)),11,1)-1)),(((HEX2DEC(A1167)/60)/60)/24)+DATE(1970,1,1)+2/24,(((HEX2DEC(A1167)/60)/60)/24)+DATE(1970,1,1)+1/24) -> 45322.895 | M1167: =IF('tab4'!$B1167=0,0,IF('tab4'!$B1167=1,1,IF('tab4'!$B1167=4,2,IF('tab4'!$B1167=5,3,IF('tab4'!$B1167=6,4,IF(AND('tab4'!$B1167=80,$X$2=2),0,-1)))))) -> 0 | N1167: =IF('tab4'!$C1167=0,0,IF('tab4'!$C1167=1,1,IF('tab4'!$C1167=4,2,IF('tab4'!$C1167=5,3,IF('tab4'!$C1167=6,4,IF(AND('tab4'!$C1167=80,$X$2=2),0,-1)))))) -> 0 | O1167: =D1167 -> 0 | P1167: =E1167 -> 0 | Q1167: =F1167 -> 0 | R1167: =G1167 -> 0 | S1167: =IF(HEX2DEC(H1167) >= 32768, (HEX2DEC(H1167) - 65535 - 1)/10, IF(HEX2DEC(H1167) = 32767, IF($X$2=2, S1168, 32767), HEX2DEC(H1167)/10 )) -> 4.4 | T1167: =IF(HEX2DEC(I1167) >= 32768, (HEX2DEC(I1167) - 65535 - 1)/10, IF(HEX2DEC(I1167) = 32767, IF($X$2=2, T1168, 32767), HEX2DEC(I1167)/10 )) -> 3.6 | U1167: =IF(HEX2DEC(J1167) >= 32768, (HEX2DEC(J1167) - 65535 - 1)/10, IF(HEX2DEC(J1167) = 32767, IF($X$2=2, U1168, 32767), IF(OR(AND(H1167="7fff", I1167="7fff", J1167="0",$X$2=2),AND(ABS(T1167)>2, J1167="0",$X$2=2)),U1168,HEX2DEC(J1167)/10 ))) -> 2.6
A1168: 65babbb9 | B1168: 0 | C1168: 4 | D1168: 0 | E1168: 1 | F1168: 0 | G1168: 0 | H1168: 1d | I1168: 13 | J1168: c | L1168: =IF(AND((((HEX2DEC(A1168)/60)/60)/24)+DATE(1970,1,1) >= DATE(YEAR((((HEX2DEC(A1168)/60)/60)/24)+DATE(1970,1,1)),3,24)+WEEKDAY(DATE(YEAR((((HEX2DEC(A1168)/60)/60)/24)+DATE(1970,1,1)),3,31)-1), (((HEX2DEC(A1168)/60)/60)/24)+DATE(1970,1,1) < DATE(YEAR((((HEX2DEC(A1168)/60)/60)/24)+DATE(1970,1,1)),11,1)+26-WEEKDAY(DATE(YEAR((((HEX2DEC(A1168)/60)/60)/24)+DATE(1970,1,1)),11,1)-1)),(((HEX2DEC(A1168)/60)/60)/24)+DATE(1970,1,1)+2/24,(((HEX2DEC(A1168)/60)/60)/24)+DATE(1970,1,1)+1/24) -> 45322.937 | M1168: =IF('tab4'!$B1168=0,0,IF('tab4'!$B1168=1,1,IF('tab4'!$B1168=4,2,IF('tab4'!$B1168=5,3,IF('tab4'!$B1168=6,4,IF(AND('tab4'!$B1168=80,$X$2=2),0,-1)))))) -> 0 | N1168: =IF('tab4'!$C1168=0,0,IF('tab4'!$C1168=1,1,IF('tab4'!$C1168=4,2,IF('tab4'!$C1168=5,3,IF('tab4'!$C1168=6,4,IF(AND('tab4'!$C1168=80,$X$2=2),0,-1)))))) -> 2 | O1168: =D1168 -> 0 | P1168: =E1168 -> 1 | Q1168: =F1168 -> 0 | R1168: =G1168 -> 0 | S1168: =IF(HEX2DEC(H1168) >= 32768, (HEX2DEC(H1168) - 65535 - 1)/10, IF(HEX2DEC(H1168) = 32767, IF($X$2=2, S1169, 32767), HEX2DEC(H1168)/10 )) -> 2.9 | T1168: =IF(HEX2DEC(I1168) >= 32768, (HEX2DEC(I1168) - 65535 - 1)/10, IF(HEX2DEC(I1168) = 32767, IF($X$2=2, T1169, 32767), HEX2DEC(I1168)/10 )) -> 1.9 | U1168: =IF(HEX2DEC(J1168) >= 32768, (HEX2DEC(J1168) - 65535 - 1)/10, IF(HEX2DEC(J1168) = 32767, IF($X$2=2, U1169, 32767), IF(OR(AND(H1168="7fff", I1168="7fff", J1168="0",$X$2=2),AND(ABS(T1168)>2, J1168="0",$X$2=2)),U1169,HEX2DEC(J1168)/10 ))) -> 1.2
A1169: 65bad7d9 | B1169: 0 | C1169: 4 | D1169: 0 | E1169: 1 | F1169: 0 | G1169: 0 | H1169: b | I1169: ffff | J1169: 4 | L1169: =IF(AND((((HEX2DEC(A1169)/60)/60)/24)+DATE(1970,1,1) >= DATE(YEAR((((HEX2DEC(A1169)/60)/60)/24)+DATE(1970,1,1)),3,24)+WEEKDAY(DATE(YEAR((((HEX2DEC(A1169)/60)/60)/24)+DATE(1970,1,1)),3,31)-1), (((HEX2DEC(A1169)/60)/60)/24)+DATE(1970,1,1) < DATE(YEAR((((HEX2DEC(A1169)/60)/60)/24)+DATE(1970,1,1)),11,1)+26-WEEKDAY(DATE(YEAR((((HEX2DEC(A1169)/60)/60)/24)+DATE(1970,1,1)),11,1)-1)),(((HEX2DEC(A1169)/60)/60)/24)+DATE(1970,1,1)+2/24,(((HEX2DEC(A1169)/60)/60)/24)+DATE(1970,1,1)+1/24) -> 45323.02 | M1169: =IF('tab4'!$B1169=0,0,IF('tab4'!$B1169=1,1,IF('tab4'!$B1169=4,2,IF('tab4'!$B1169=5,3,IF('tab4'!$B1169=6,4,IF(AND('tab4'!$B1169=80,$X$2=2),0,-1)))))) -> 0 | N1169: =IF('tab4'!$C1169=0,0,IF('tab4'!$C1169=1,1,IF('tab4'!$C1169=4,2,IF('tab4'!$C1169=5,3,IF('tab4'!$C1169=6,4,IF(AND('tab4'!$C1169=80,$X$2=2),0,-1)))))) -> 2 | O1169: =D1169 -> 0 | P1169: =E1169 -> 1 | Q1169: =F1169 -> 0 | R1169: =G1169 -> 0 | S1169: =IF(HEX2DEC(H1169) >= 32768, (HEX2DEC(H1169) - 65535 - 1)/10, IF(HEX2DEC(H1169) = 32767, IF($X$2=2, S1170, 32767), HEX2DEC(H1169)/10 )) -> 1.1 | T1169: =IF(HEX2DEC(I1169) >= 32768, (HEX2DEC(I1169) - 65535 - 1)/10, IF(HEX2DEC(I1169) = 32767, IF($X$2=2, T1170, 32767), HEX2DEC(I1169)/10 )) -> -0.1 | U1169: =IF(HEX2DEC(J1169) >= 32768, (HEX2DEC(J1169) - 65535 - 1)/10, IF(HEX2DEC(J1169) = 32767, IF($X$2=2, U1170, 32767), IF(OR(AND(H1169="7fff", I1169="7fff", J1169="0",$X$2=2),AND(ABS(T1169)>2, J1169="0",$X$2=2)),U1170,HEX2DEC(J1169)/10 ))) -> 0.4
A1170: 65baf3f9 | B1170: 0 | C1170: 4 | D1170: 0 | E1170: 1 | F1170: 0 | G1170: 0 | H1170: fff8 | I1170: ffeb | J1170: fff3 | L1170: =IF(AND((((HEX2DEC(A1170)/60)/60)/24)+DATE(1970,1,1) >= DATE(YEAR((((HEX2DEC(A1170)/60)/60)/24)+DATE(1970,1,1)),3,24)+WEEKDAY(DATE(YEAR((((HEX2DEC(A1170)/60)/60)/24)+DATE(1970,1,1)),3,31)-1), (((HEX2DEC(A1170)/60)/60)/24)+DATE(1970,1,1) < DATE(YEAR((((HEX2DEC(A1170)/60)/60)/24)+DATE(1970,1,1)),11,1)+26-WEEKDAY(DATE(YEAR((((HEX2DEC(A1170)/60)/60)/24)+DATE(1970,1,1)),11,1)-1)),(((HEX2DEC(A1170)/60)/60)/24)+DATE(1970,1,1)+2/24,(((HEX2DEC(A1170)/60)/60)/24)+DATE(1970,1,1)+1/24) -> 45323.104 | M1170: =IF('tab4'!$B1170=0,0,IF('tab4'!$B1170=1,1,IF('tab4'!$B1170=4,2,IF('tab4'!$B1170=5,3,IF('tab4'!$B1170=6,4,IF(AND('tab4'!$B1170=80,$X$2=2),0,-1)))))) -> 0 | N1170: =IF('tab4'!$C1170=0,0,IF('tab4'!$C1170=1,1,IF('tab4'!$C1170=4,2,IF('tab4'!$C1170=5,3,IF('tab4'!$C1170=6,4,IF(AND('tab4'!$C1170=80,$X$2=2),0,-1)))))) -> 2 | O1170: =D1170 -> 0 | P1170: =E1170 -> 1 | Q1170: =F1170 -> 0 | R1170: =G1170 -> 0 | S1170: =IF(HEX2DEC(H1170) >= 32768, (HEX2DEC(H1170) - 65535 - 1)/10, IF(HEX2DEC(H1170) = 32767, IF($X$2=2, S1171, 32767), HEX2DEC(H1170)/10 )) -> -0.8 | T1170: =IF(HEX2DEC(I1170) >= 32768, (HEX2DEC(I1170) - 65535 - 1)/10, IF(HEX2DEC(I1170) = 32767, IF($X$2=2, T1171, 32767), HEX2DEC(I1170)/10 )) -> -2.1 | U1170: =IF(HEX2DEC(J1170) >= 32768, (HEX2DEC(J1170) - 65535 - 1)/10, IF(HEX2DEC(J1170) = 32767, IF($X$2=2, U1171, 32767), IF(OR(AND(H1170="7fff", I1170="7fff", J1170="0",$X$2=2),AND(ABS(T1170)>2, J1170="0",$X$2=2)),U1171,HEX2DEC(J1170)/10 ))) -> -1.3
A1171: 65bb1019 | B1171: 0 | C1171: 4 | D1171: 0 | E1171: 1 | F1171: 0 | G1171: 0 | H1171: 1 | I1171: fffc | J1171: c | L1171: =IF(AND((((HEX2DEC(A1171)/60)/60)/24)+DATE(1970,1,1) >= DATE(YEAR((((HEX2DEC(A1171)/60)/60)/24)+DATE(1970,1,1)),3,24)+WEEKDAY(DATE(YEAR((((HEX2DEC(A1171)/60)/60)/24)+DATE(1970,1,1)),3,31)-1), (((HEX2DEC(A1171)/60)/60)/24)+DATE(1970,1,1) < DATE(YEAR((((HEX2DEC(A1171)/60)/60)/24)+DATE(1970,1,1)),11,1)+26-WEEKDAY(DATE(YEAR((((HEX2DEC(A1171)/60)/60)/24)+DATE(1970,1,1)),11,1)-1)),(((HEX2DEC(A1171)/60)/60)/24)+DATE(1970,1,1)+2/24,(((HEX2DEC(A1171)/60)/60)/24)+DATE(1970,1,1)+1/24) -> 45323.187 | M1171: =IF('tab4'!$B1171=0,0,IF('tab4'!$B1171=1,1,IF('tab4'!$B1171=4,2,IF('tab4'!$B1171=5,3,IF('tab4'!$B1171=6,4,IF(AND('tab4'!$B1171=80,$X$2=2),0,-1)))))) -> 0 | N1171: =IF('tab4'!$C1171=0,0,IF('tab4'!$C1171=1,1,IF('tab4'!$C1171=4,2,IF('tab4'!$C1171=5,3,IF('tab4'!$C1171=6,4,IF(AND('tab4'!$C1171=80,$X$2=2),0,-1)))))) -> 2 | O1171: =D1171 -> 0 | P1171: =E1171 -> 1 | Q1171: =F1171 -> 0 | R1171: =G1171 -> 0 | S1171: =IF(HEX2DEC(H1171) >= 32768, (HEX2DEC(H1171) - 65535 - 1)/10, IF(HEX2DEC(H1171) = 32767, IF($X$2=2, S1172, 32767), HEX2DEC(H1171)/10 )) -> 0.1 | T1171: =IF(HEX2DEC(I1171) >= 32768, (HEX2DEC(I1171) - 65535 - 1)/10, IF(HEX2DEC(I1171) = 32767, IF($X$2=2, T1172, 32767), HEX2DEC(I1171)/10 )) -> -0.4 | U1171: =IF(HEX2DEC(J1171) >= 32768, (HEX2DEC(J1171) - 65535 - 1)/10, IF(HEX2DEC(J1171) = 32767, IF($X$2=2, U1172, 32767), IF(OR(AND(H1171="7fff", I1171="7fff", J1171="0",$X$2=2),AND(ABS(T1171)>2, J1171="0",$X$2=2)),U1172,HEX2DEC(J1171)/10 ))) -> 1.2
...
